Workbook

Sheet 2025月度汇总表
D1: 中国国航 | E1: 中国东航 | F1: 南方航空 | G1: 吉祥航空 | H1: 春秋航空 | I1: 海航控股
B3: 【申万交运】2026年3月航空公司数据汇总
B4: 总量 | D4: 中国国航 | E4: 中国东航 | F4: 南方航空 | G4: 吉祥航空 | H4: 春秋航空 | I4: 海航控股
B5: ASK（百万座公里） | C5: 当期值 | D5: =INDIRECT("'"&D$1&"'!B150") -> 31820.6 | E5: =INDIRECT("'"&E$1&"'!B150") -> 27502.31 | F5: =INDIRECT("'"&F$1&"'!B150") -> 32943.27 | G5: =INDIRECT("'"&G$1&"'!B150") -> 4817.8391 | H5: =INDIRECT("'"&H$1&"'!B150") -> 5655.4537 | I5: =INDIRECT("'"&I$1&"'!B150") -> 13472.35
C6: 同比2025 | D6: =INDIRECT("'"&D$1&"'!C150") -> 0.107335 | E6: =INDIRECT("'"&E$1&"'!C150") -> 0.10634457 | F6: =INDIRECT("'"&F$1&"'!C150") -> 0.12365185 | G6: =INDIRECT("'"&G$1&"'!C150") -> 0.041674558 | H6: =INDIRECT("'"&H$1&"'!C150") -> 0.22910143 | I6: =INDIRECT("'"&I$1&"'!C150") -> 0.059432693
C7: 同比2019 | D7: =INDIRECT("'"&D$1&"'!D150") -> 0.342919 | E7: =INDIRECT("'"&E$1&"'!D150") -> 0.27336592 | F7: =INDIRECT("'"&F$1&"'!D150") -> 0.20126262 | G7: =INDIRECT("'"&G$1&"'!D150") -> 0.47285515 | H7: =INDIRECT("'"&H$1&"'!D150") -> 0.65086335 | I7: =INDIRECT("'"&I$1&"'!D150") -> -0.080089285
B8: RPK（百万客公里） | C8: 当期值 | D8: =INDIRECT("'"&D$1&"'!N150") -> 27457.4 | E8: =INDIRECT("'"&E$1&"'!N150") -> 24385.14 | F8: =INDIRECT("'"&F$1&"'!N150") -> 28260.15 | G8: =INDIRECT("'"&G$1&"'!N150") -> 4257.0313 | H8: =INDIRECT("'"&H$1&"'!N150") -> 5227.3172 | I8: =INDIRECT("'"&I$1&"'!N150") -> 11456.18
C9: 同比2025 | D9: =INDIRECT("'"&D$1&"'!O150") -> 0.19877753 | E9: =INDIRECT("'"&E$1&"'!O150") -> 0.16556022 | F9: =INDIRECT("'"&F$1&"'!O150") -> 0.13756447 | G9: =INDIRECT("'"&G$1&"'!O150") -> 0.089168943 | H9: =INDIRECT("'"&H$1&"'!O150") -> 0.26600626 | I9: =INDIRECT("'"&I$1&"'!O150") -> 0.09198619
C10: 同比2019 | D10: =INDIRECT("'"&D$1&"'!P150") -> 0.43625179 | E10: =INDIRECT("'"&E$1&"'!P150") -> 0.3650024 | F10: =INDIRECT("'"&F$1&"'!P150") -> 0.23937698 | G10: =INDIRECT("'"&G$1&"'!P150") -> 0.50962775 | H10: =INDIRECT("'"&H$1&"'!P150") -> 0.65211993 | I10: =INDIRECT("'"&I$1&"'!P150") -> -0.055637851
B11: 旅客运输量（千人） | C11: 当期值 | D11: =INDIRECT("'"&D$1&"'!Z150") -> 14309.3 | E11: =INDIRECT("'"&E$1&"'!Z150") -> 13006.57 | F11: =INDIRECT("'"&F$1&"'!Z150") -> 14597.53 | G11: =INDIRECT("'"&G$1&"'!Z150") -> 2265.68 | H11: =INDIRECT("'"&H$1&"'!Z150") -> 2882.89 | I11: =INDIRECT("'"&I$1&"'!Z150") -> 6014.61
C12: 同比2025 | D12: =INDIRECT("'"&D$1&"'!AA150") -> 0.1512555 | E12: =INDIRECT("'"&E$1&"'!AA150") -> 0.11020187 | F12: =INDIRECT("'"&F$1&"'!AA150") -> 0.10097249 | G12: =INDIRECT("'"&G$1&"'!AA150") -> 0.036568684 | H12: =INDIRECT("'"&H$1&"'!AA150") -> 0.21686625 | I12: =INDIRECT("'"&I$1&"'!AA150") -> 0.09075725
C13: 同比2019 | D13: =INDIRECT("'"&D$1&"'!AB150") -> 0.5096587 | E13: =INDIRECT("'"&E$1&"'!AB150") -> 0.22171239 | F13: =INDIRECT("'"&F$1&"'!AB150") -> 0.20078459 | G13: =INDIRECT("'"&G$1&"'!AB150") -> 0.2916555 | H13: =INDIRECT("'"&H$1&"'!AB150") -> 0.63221872 | I13: =INDIRECT("'"&I$1&"'!AB150") -> -0.14490743
B14: 客座率（%） | C14: 当期值 | D14: =INDIRECT("'"&D$1&"'!AL150") -> 86.3 | E14: =INDIRECT("'"&E$1&"'!AL150") -> 88.67 | F14: =INDIRECT("'"&F$1&"'!AL150") -> 85.78 | G14: =INDIRECT("'"&G$1&"'!AL150") -> 88.36 | H14: =INDIRECT("'"&H$1&"'!AL150") -> 92.43 | I14: =INDIRECT("'"&I$1&"'!AL150") -> 85.03
C15: 同比2025 | D15: =INDIRECT("'"&D$1&"'!AM150") -> 6.6 | E15: =INDIRECT("'"&E$1&"'!AM150") -> 4.51 | F15: =INDIRECT("'"&F$1&"'!AM150") -> 1.04 | G15: =INDIRECT("'"&G$1&"'!AM150") -> 3.85 | H15: =INDIRECT("'"&H$1&"'!AM150") -> 2.69 | I15: =INDIRECT("'"&I$1&"'!AM150") -> 2.53
C16: 同比2019 | D16: =INDIRECT("'"&D$1&"'!AN150") -> 5.6 | E16: =INDIRECT("'"&E$1&"'!AN150") -> 5.96 | F16: =INDIRECT("'"&F$1&"'!AN150") -> 0.031629585 | G16: =INDIRECT("'"&G$1&"'!AN150") -> 2.15 | H16: =INDIRECT("'"&H$1&"'!AN150") -> 0.07 | I16: =INDIRECT("'"&I$1&"'!AN150") -> 2.2
B17: 机队数（架） | C17: 当期值 | D17: =INDIRECT("'"&D$1&"'!AX150") -> 960 | E17: =INDIRECT("'"&E$1&"'!AX150") -> 823 | F17: =INDIRECT("'"&F$1&"'!AX150") -> 971 | G17: =INDIRECT("'"&G$1&"'!AX150") -> 129 | H17: =INDIRECT("'"&H$1&"'!AX150") -> 134 | I17: =INDIRECT("'"&I$1&"'!AX150") -> 362
C18: 同比2025 | D18: =INDIRECT("'"&D$1&"'!AY150") -> 0.027837259 | E18: =INDIRECT("'"&E$1&"'!AY150") -> 0.0085784314 | F18: =INDIRECT("'"&F$1&"'!AY150") -> 0.041845494 | G18: =INDIRECT("'"&G$1&"'!AY150") -> 0 | H18: =INDIRECT("'"&H$1&"'!AY150") -> 0.022900763 | I18: =INDIRECT("'"&I$1&"'!AY150") -> 0.031339031
C19: 同比2019 | D19: =INDIRECT("'"&D$1&"'!AZ150") -> 0.42011834 | E19: =INDIRECT("'"&E$1&"'!AZ150") -> 0.18759019 | F19: =INDIRECT("'"&F$1&"'!AZ150") -> 0.14639906 | G19: =INDIRECT("'"&G$1&"'!AZ150") -> 0.43333333 | H19: =INDIRECT("'"&H$1&"'!AZ150") -> 0.61445783 | I19: =INDIRECT("'"&I$1&"'!AZ150") -> -0.23628692
B20: 国内 | D20: 中国国航 | E20: 中国东航 | F20: 南方航空 | G20: 吉祥航空 | H20: 春秋航空 | I20: 海航控股
B21: ASK（百万座公里） | C21: 当期值 | D21: =INDIRECT("'"&D$1&"'!E150") -> 21975.9 | E21: =INDIRECT("'"&E$1&"'!E150") -> 17978.13 | F21: =INDIRECT("'"&F$1&"'!E150") -> 23734.77 | G21: =INDIRECT("'"&G$1&"'!E150") -> 3464.331 | H21: =INDIRECT("'"&H$1&"'!E150") -> 4382.2465 | I21: =INDIRECT("'"&I$1&"'!E150") -> 10677.91
C22: 同比2025 | D22: =INDIRECT("'"&D$1&"'!F150") -> 0.11670698 | E22: =INDIRECT("'"&E$1&"'!F150") -> 0.11296053 | F22: =INDIRECT("'"&F$1&"'!F150") -> 0.11109202 | G22: =INDIRECT("'"&G$1&"'!F150") -> 0.082508955 | H22: =INDIRECT("'"&H$1&"'!F150") -> 0.23029215 | I22: =INDIRECT("'"&I$1&"'!F150") -> 0.087667027
C23: 同比2019 | D23: =INDIRECT("'"&D$1&"'!G150") -> 0.60201054 | E23: =INDIRECT("'"&E$1&"'!G150") -> 0.29532525 | F23: =INDIRECT("'"&F$1&"'!G150") -> 0.25676281 | G23: =INDIRECT("'"&G$1&"'!G150") -> 0.28159497 | H23: =INDIRECT("'"&H$1&"'!G150") -> 1.0064346 | I23: =INDIRECT("'"&I$1&"'!G150") -> -0.02218195
B24: RPK（百万客公里） | C24: 当期值 | D24: =INDIRECT("'"&D$1&"'!Q150") -> 18798.9 | E24: =INDIRECT("'"&E$1&"'!Q150") -> 15784.94 | F24: =INDIRECT("'"&F$1&"'!Q150") -> 20173.29 | G24: =INDIRECT("'"&G$1&"'!Q150") -> 3055.6602 | H24: =INDIRECT("'"&H$1&"'!Q150") -> 4061.1856 | I24: =INDIRECT("'"&I$1&"'!Q150") -> 9163.8
C25: 同比2025 | D25: =INDIRECT("'"&D$1&"'!R150") -> 0.16875874 | E25: =INDIRECT("'"&E$1&"'!R150") -> 0.14001717 | F25: =INDIRECT("'"&F$1&"'!R150") -> 0.10567959 | G25: =INDIRECT("'"&G$1&"'!R150") -> 0.087291149 | H25: =INDIRECT("'"&H$1&"'!R150") -> 0.25828837 | I25: =INDIRECT("'"&I$1&"'!R150") -> 0.09283583
C26: 同比2019 | D26: =INDIRECT("'"&D$1&"'!S150") -> 0.67282742 | E26: =INDIRECT("'"&E$1&"'!S150") -> 0.35240096 | F26: =INDIRECT("'"&F$1&"'!S150") -> 0.28741001 | G26: =INDIRECT("'"&G$1&"'!S150") -> 0.30127771 | H26: =INDIRECT("'"&H$1&"'!S150") -> 0.99724716 | I26: =INDIRECT("'"&I$1&"'!S150") -> -0.049325363
B27: 旅客运输量（千人） | C27: 当期值 | D27: =INDIRECT("'"&D$1&"'!AC150") -> 12138 | E27: =INDIRECT("'"&E$1&"'!AC150") -> 10835.24 | F27: =INDIRECT("'"&F$1&"'!AC150") -> 12486.24 | G27: =INDIRECT("'"&G$1&"'!AC150") -> 1932.96 | H27: =INDIRECT("'"&H$1&"'!AC150") -> 2363.77 | I27: =INDIRECT("'"&I$1&"'!AC150") -> 5630.58
C28: 同比2025 | D28: =INDIRECT("'"&D$1&"'!AD150") -> 0.14133654 | E28: =INDIRECT("'"&E$1&"'!AD150") -> 0.10718227 | F28: =INDIRECT("'"&F$1&"'!AD150") -> 0.083526052 | G28: =INDIRECT("'"&G$1&"'!AD150") -> 0.05931869 | H28: =INDIRECT("'"&H$1&"'!AD150") -> 0.2437229 | I28: =INDIRECT("'"&I$1&"'!AD150") -> 0.089329348
C29: 同比2019 | D29: =INDIRECT("'"&D$1&"'!AE150") -> 0.61109636 | E29: =INDIRECT("'"&E$1&"'!AE150") -> 0.22074419 | F29: =INDIRECT("'"&F$1&"'!AE150") -> 0.21227397 | G29: =INDIRECT("'"&G$1&"'!AE150") -> 0.26738178 | H29: =INDIRECT("'"&H$1&"'!AE150") -> 0.87526378 | I29: =INDIRECT("'"&I$1&"'!AE150") -> -0.14305413
B30: 客座率（%） | C30: 当期值 | D30: =INDIRECT("'"&D$1&"'!AO150") -> 85.5 | E30: =INDIRECT("'"&E$1&"'!AO150") -> 87.8 | F30: =INDIRECT("'"&F$1&"'!AO150") -> 84.99 | G30: =INDIRECT("'"&G$1&"'!AO150") -> 88.2 | H30: =INDIRECT("'"&H$1&"'!AO150") -> 92.67 | I30: =INDIRECT("'"&I$1&"'!AO150") -> 85.82
C31: 同比2025 | D31: =INDIRECT("'"&D$1&"'!AP150") -> 3.8 | E31: =INDIRECT("'"&E$1&"'!AP150") -> 2.08 | F31: =INDIRECT("'"&F$1&"'!AP150") -> -0.42 | G31: =INDIRECT("'"&G$1&"'!AP150") -> 0.38 | H31: =INDIRECT("'"&H$1&"'!AP150") -> 2.06 | I31: =INDIRECT("'"&I$1&"'!AP150") -> 0.41
C32: 同比2019 | D32: =INDIRECT("'"&D$1&"'!AQ150") -> 3.6 | E32: =INDIRECT("'"&E$1&"'!AQ150") -> 3.7 | F32: =INDIRECT("'"&F$1&"'!AQ150") -> 0.024346149 | G32: =INDIRECT("'"&G$1&"'!AQ150") -> 1.33 | H32: =INDIRECT("'"&H$1&"'!AQ150") -> -0.43 | I32: =INDIRECT("'"&I$1&"'!AQ150") -> -2.45
B33: 国际 | C33: 国际 | D33: 中国国航 | E33: 中国东航 | F33: 南方航空 | G33: 吉祥航空 | H33: 春秋航空 | I33: 海航控股
B34: ASK（百万座公里） | C34: 当期值 | D34: =INDIRECT("'"&D$1&"'!H150") -> 8954.1 | E34: =INDIRECT("'"&E$1&"'!H150") -> 8989.5 | F34: =INDIRECT("'"&F$1&"'!H150") -> 8944.63 | G34: =INDIRECT("'"&G$1&"'!H150") -> 1313.8883 | H34: =INDIRECT("'"&H$1&"'!H150") -> 1230.9309 | I34: =INDIRECT("'"&I$1&"'!H150") -> 2763.42
C35: 同比2025 | D35: =INDIRECT("'"&D$1&"'!I150") -> 0.085016662 | E35: =INDIRECT("'"&E$1&"'!I150") -> 0.097931402 | F35: =INDIRECT("'"&F$1&"'!I150") -> 0.15981619 | G35: =INDIRECT("'"&G$1&"'!I150") -> -0.047354702 | H35: =INDIRECT("'"&H$1&"'!I150") -> 0.21901165 | I35: =INDIRECT("'"&I$1&"'!I150") -> -0.035213038
C36: 同比2019 | D36: =INDIRECT("'"&D$1&"'!J150") -> -0.012669534 | E36: =INDIRECT("'"&E$1&"'!J150") -> 0.25432375 | F36: =INDIRECT("'"&F$1&"'!J150") -> 0.095865555 | G36: =INDIRECT("'"&G$1&"'!J150") -> 1.5540777 | H36: =INDIRECT("'"&H$1&"'!J150") -> 0.09858512 | I36: =INDIRECT("'"&I$1&"'!J150") -> -0.24682546
B37: RPK（百万客公里） | C37: 当期值 | D37: =INDIRECT("'"&D$1&"'!T150") -> 7965.3 | E37: =INDIRECT("'"&E$1&"'!T150") -> 8141.83 | F37: =INDIRECT("'"&F$1&"'!T150") -> 7870.34 | G37: =INDIRECT("'"&G$1&"'!T150") -> 1166.7813 | H37: =INDIRECT("'"&H$1&"'!T150") -> 1127.6315 | I37: =INDIRECT("'"&I$1&"'!T150") -> 2269.56
C38: 同比2025 | D38: =INDIRECT("'"&D$1&"'!U150") -> 0.2762245 | E38: =INDIRECT("'"&E$1&"'!U150") -> 0.2229928 | F38: =INDIRECT("'"&F$1&"'!U150") -> 0.22720951 | G38: =INDIRECT("'"&G$1&"'!U150") -> 0.10187263 | H38: =INDIRECT("'"&H$1&"'!U150") -> 0.28911213 | I38: =INDIRECT("'"&I$1&"'!U150") -> 0.08854409
C39: 同比2019 | D39: =INDIRECT("'"&D$1&"'!V150") -> 0.11555699 | E39: =INDIRECT("'"&E$1&"'!V150") -> 0.42138902 | F39: =INDIRECT("'"&F$1&"'!V150") -> 0.15112592 | G39: =INDIRECT("'"&G$1&"'!V150") -> 1.7430945 | H39: =INDIRECT("'"&H$1&"'!V150") -> 0.10744728 | I39: =INDIRECT("'"&I$1&"'!V150") -> -0.071329198
B40: 旅客运输量（千人） | C40: 当期值 | D40: =INDIRECT("'"&D$1&"'!AF150") -> 1717.4 | E40: =INDIRECT("'"&E$1&"'!AF150") -> 1839.55 | F40: =INDIRECT("'"&F$1&"'!AF150") -> 1949.25 | G40: =INDIRECT("'"&G$1&"'!AF150") -> 307.17 | H40: =INDIRECT("'"&H$1&"'!AF150") -> 492.22 | I40: =INDIRECT("'"&I$1&"'!AF150") -> 359.27
C41: 同比2025 | D41: =INDIRECT("'"&D$1&"'!AG150") -> 0.21097165 | E41: =INDIRECT("'"&E$1&"'!AG150") -> 0.13102155 | F41: =INDIRECT("'"&F$1&"'!AG150") -> 0.2217403 | G41: =INDIRECT("'"&G$1&"'!AG150") -> -0.078701899 | H41: =INDIRECT("'"&H$1&"'!AG150") -> 0.094211275 | I41: =INDIRECT("'"&I$1&"'!AG150") -> 0.10913188
...

Sheet 2025季度汇总表
D1: 中国国航 | E1: 中国东航 | F1: 南方航空 | G1: 吉祥航空 | H1: 春秋航空 | I1: 海航控股
B3: 【申万交运】2025年Q4航空数据汇总
B4: 总量 | D4: 中国国航 | E4: 中国东航 | F4: 南方航空 | G4: 吉祥航空 | H4: 春秋航空 | I4: 海航控股
B5: ASK（百万座公里） | C5: 当期值 | D5: =INDIRECT("'"&D$1&"'!B189") -> 89116.5 | E5: =INDIRECT("'"&E$1&"'!B189") -> 77080.97 | F5: =INDIRECT("'"&F$1&"'!B189") -> 90918.45 | G5: =INDIRECT("'"&G$1&"'!B189") -> 14026.494 | H5: =INDIRECT("'"&H$1&"'!B189") -> 14759.844 | I5: =INDIRECT("'"&I$1&"'!B189") -> 38018.11
C6: 同比2024 | D6: =INDIRECT("'"&D$1&"'!C189") -> 0.040960216 | E6: =INDIRECT("'"&E$1&"'!C189") -> 0.084717816 | F6: =INDIRECT("'"&F$1&"'!C189") -> 0.060369923 | G6: =INDIRECT("'"&G$1&"'!C189") -> 0.017196808 | H6: =INDIRECT("'"&H$1&"'!C189") -> 0.12095587 | I6: =INDIRECT("'"&I$1&"'!C189") -> 0.11393985
C7: 同比2019 | D7: =INDIRECT("'"&D$1&"'!D189") -> 0.24796945 | E7: =INDIRECT("'"&E$1&"'!D189") -> 0.17380966 | F7: =INDIRECT("'"&F$1&"'!D189") -> 0.1019785 | G7: =INDIRECT("'"&G$1&"'!D189") -> 0.4020521 | H7: =INDIRECT("'"&H$1&"'!D189") -> 0.38706622 | I7: =INDIRECT("'"&I$1&"'!D189") -> -0.15251291
B8: RPK（百万客公里） | C8: 当期值 | D8: =INDIRECT("'"&D$1&"'!N189") -> 72365.4 | E8: =INDIRECT("'"&E$1&"'!N189") -> 66005.64 | F8: =INDIRECT("'"&F$1&"'!N189") -> 77785.24 | G8: =INDIRECT("'"&G$1&"'!N189") -> 12109.88 | H8: =INDIRECT("'"&H$1&"'!N189") -> 13348.786 | I8: =INDIRECT("'"&I$1&"'!N189") -> 31330.71
C9: 同比2024 | D9: =INDIRECT("'"&D$1&"'!O189") -> 0.069506846 | E9: =INDIRECT("'"&E$1&"'!O189") -> 0.13606699 | F9: =INDIRECT("'"&F$1&"'!O189") -> 0.090767384 | G9: =INDIRECT("'"&G$1&"'!O189") -> 0.051017574 | H9: =INDIRECT("'"&H$1&"'!O189") -> 0.10871267 | I9: =INDIRECT("'"&I$1&"'!O189") -> 0.10864551
C10: 同比2019 | D10: =INDIRECT("'"&D$1&"'!P189") -> 0.25821797 | E10: =INDIRECT("'"&E$1&"'!P189") -> 0.21471043 | F10: =INDIRECT("'"&F$1&"'!P189") -> 0.14398403 | G10: =INDIRECT("'"&G$1&"'!P189") -> 0.41509835 | H10: =INDIRECT("'"&H$1&"'!P189") -> 0.37477876 | I10: =INDIRECT("'"&I$1&"'!P189") -> -0.15684915
B11: 旅客运输量（千人） | C11: 当期值 | D11: =INDIRECT("'"&D$1&"'!Z189") -> 38999.2 | E11: =INDIRECT("'"&E$1&"'!Z189") -> 36719.61 | F11: =INDIRECT("'"&F$1&"'!Z189") -> 41330.93 | G11: =INDIRECT("'"&G$1&"'!Z189") -> 6859.18 | H11: =INDIRECT("'"&H$1&"'!Z189") -> 7775.93 | I11: =INDIRECT("'"&I$1&"'!Z189") -> 16492.77
C12: 同比2024 | D12: =INDIRECT("'"&D$1&"'!AA189") -> 0.047197347 | E12: =INDIRECT("'"&E$1&"'!AA189") -> 0.095455393 | F12: =INDIRECT("'"&F$1&"'!AA189") -> 0.060979673 | G12: =INDIRECT("'"&G$1&"'!AA189") -> -0.0018321335 | H12: =INDIRECT("'"&H$1&"'!AA189") -> 0.13255829 | I12: =INDIRECT("'"&I$1&"'!AA189") -> 0.052079054
C13: 同比2019 | D13: =INDIRECT("'"&D$1&"'!AB189") -> 0.3910004 | E13: =INDIRECT("'"&E$1&"'!AB189") -> 0.14284429 | F13: =INDIRECT("'"&F$1&"'!AB189") -> 0.13563702 | G13: =INDIRECT("'"&G$1&"'!AB189") -> 0.23172484 | H13: =INDIRECT("'"&H$1&"'!AB189") -> 0.40274418 | I13: =INDIRECT("'"&I$1&"'!AB189") -> -0.20688695
B14: 客座率（%） | C14: 当期值 | D14: =INDIRECT("'"&D$1&"'!AL189") -> 81.233333 | E14: =INDIRECT("'"&E$1&"'!AL189") -> 85.633333 | F14: =INDIRECT("'"&F$1&"'!AL189") -> 85.556667 | G14: =INDIRECT("'"&G$1&"'!AL189") -> 86.336667 | H14: =INDIRECT("'"&H$1&"'!AL189") -> 90.446667 | I14: =INDIRECT("'"&I$1&"'!AL189") -> 82.413333
C15: 同比2024 | D15: =INDIRECT("'"&D$1&"'!AM189") -> 2.2 | E15: =INDIRECT("'"&E$1&"'!AM189") -> 3.8766667 | F15: =INDIRECT("'"&F$1&"'!AM189") -> 2.39 | G15: =INDIRECT("'"&G$1&"'!AM189") -> 2.7566667 | H15: =INDIRECT("'"&H$1&"'!AM189") -> -1.0033333 | I15: =INDIRECT("'"&I$1&"'!AM189") -> -0.38
C16: 同比2019 | D16: =INDIRECT("'"&D$1&"'!AN189") -> 0.66666667 | E16: =INDIRECT("'"&E$1&"'!AN189") -> 2.87 | F16: =INDIRECT("'"&F$1&"'!AN189") -> 3.1366667 | G16: =INDIRECT("'"&G$1&"'!AN189") -> 0.79333333 | H16: =INDIRECT("'"&H$1&"'!AN189") -> -0.81 | I16: =INDIRECT("'"&I$1&"'!AN189") -> -0.42333333
B17: 国内 | D17: 中国国航 | E17: 中国东航 | F17: 南方航空 | G17: 吉祥航空 | H17: 春秋航空 | I17: 海航控股
B18: ASK（百万座公里） | C18: 当期值 | D18: =INDIRECT("'"&D$1&"'!E189") -> 60344.2 | E18: =INDIRECT("'"&E$1&"'!E189") -> 50325.39 | F18: =INDIRECT("'"&F$1&"'!E189") -> 65948.29 | G18: =INDIRECT("'"&G$1&"'!E189") -> 9838.1061 | H18: =INDIRECT("'"&H$1&"'!E189") -> 11787.13 | I18: =INDIRECT("'"&I$1&"'!E189") -> 28764.37
C19: 同比2024 | D19: =INDIRECT("'"&D$1&"'!F189") -> 0.011437804 | E19: =INDIRECT("'"&E$1&"'!F189") -> 0.037559465 | F19: =INDIRECT("'"&F$1&"'!F189") -> 0.02045844 | G19: =INDIRECT("'"&G$1&"'!F189") -> -0.10214622 | H19: =INDIRECT("'"&H$1&"'!F189") -> 0.10880427 | I19: =INDIRECT("'"&I$1&"'!F189") -> 0.025617648
C20: 同比2019 | D20: =INDIRECT("'"&D$1&"'!G189") -> 0.50071126 | E20: =INDIRECT("'"&E$1&"'!G189") -> 0.21159934 | F20: =INDIRECT("'"&F$1&"'!G189") -> 0.17747015 | G20: =INDIRECT("'"&G$1&"'!G189") -> 0.16695886 | H20: =INDIRECT("'"&H$1&"'!G189") -> 0.67859325 | I20: =INDIRECT("'"&I$1&"'!G189") -> -0.10728988
B21: RPK（百万客公里） | C21: 当期值 | D21: =INDIRECT("'"&D$1&"'!Q189") -> 50421.5 | E21: =INDIRECT("'"&E$1&"'!Q189") -> 43812.48 | F21: =INDIRECT("'"&F$1&"'!Q189") -> 56797.88 | G21: =INDIRECT("'"&G$1&"'!Q189") -> 8712.3471 | H21: =INDIRECT("'"&H$1&"'!Q189") -> 10753.903 | I21: =INDIRECT("'"&I$1&"'!Q189") -> 24692.36
C22: 同比2024 | D22: =INDIRECT("'"&D$1&"'!R189") -> 0.045887412 | E22: =INDIRECT("'"&E$1&"'!R189") -> 0.088972005 | F22: =INDIRECT("'"&F$1&"'!R189") -> 0.05061256 | G22: =INDIRECT("'"&G$1&"'!R189") -> -0.068444968 | H22: =INDIRECT("'"&H$1&"'!R189") -> 0.10296164 | I22: =INDIRECT("'"&I$1&"'!R189") -> 0.032847605
C23: 同比2019 | D23: =INDIRECT("'"&D$1&"'!S189") -> 0.52870249 | E23: =INDIRECT("'"&E$1&"'!S189") -> 0.26085864 | F23: =INDIRECT("'"&F$1&"'!S189") -> 0.22777318 | G23: =INDIRECT("'"&G$1&"'!S189") -> 0.20270571 | H23: =INDIRECT("'"&H$1&"'!S189") -> 0.65982807 | I23: =INDIRECT("'"&I$1&"'!S189") -> -0.12302976
B24: 旅客运输量（千人） | C24: 当期值 | D24: =INDIRECT("'"&D$1&"'!AC189") -> 33258 | E24: =INDIRECT("'"&E$1&"'!AC189") -> 30706.65 | F24: =INDIRECT("'"&F$1&"'!AC189") -> 35802.07 | G24: =INDIRECT("'"&G$1&"'!AC189") -> 5753.78 | H24: =INDIRECT("'"&H$1&"'!AC189") -> 6322.4 | I24: =INDIRECT("'"&I$1&"'!AC189") -> 15438.47
C25: 同比2024 | D25: =INDIRECT("'"&D$1&"'!AD189") -> 0.037500117 | E25: =INDIRECT("'"&E$1&"'!AD189") -> 0.077457694 | F25: =INDIRECT("'"&F$1&"'!AD189") -> 0.043676807 | G25: =INDIRECT("'"&G$1&"'!AD189") -> -0.049525984 | H25: =INDIRECT("'"&H$1&"'!AD189") -> 0.10648307 | I25: =INDIRECT("'"&I$1&"'!AD189") -> 0.029737278
C26: 同比2019 | D26: =INDIRECT("'"&D$1&"'!AE189") -> 0.49375469 | E26: =INDIRECT("'"&E$1&"'!AE189") -> 0.14850465 | F26: =INDIRECT("'"&F$1&"'!AE189") -> 0.16255019 | G26: =INDIRECT("'"&G$1&"'!AE189") -> 0.17427437 | H26: =INDIRECT("'"&H$1&"'!AE189") -> 0.5504971 | I26: =INDIRECT("'"&I$1&"'!AE189") -> -0.20025663
B27: 客座率（%） | C27: 当期值 | D27: =INDIRECT("'"&D$1&"'!AO189") -> 83.566667 | E27: =INDIRECT("'"&E$1&"'!AO189") -> 87.056667 | F27: =INDIRECT("'"&F$1&"'!AO189") -> 86.116667 | G27: =INDIRECT("'"&G$1&"'!AO189") -> 88.553333 | H27: =INDIRECT("'"&H$1&"'!AO189") -> 91.23 | I27: =INDIRECT("'"&I$1&"'!AO189") -> 85.843333
C28: 同比2024 | D28: =INDIRECT("'"&D$1&"'!AP189") -> 2.7666667 | E28: =INDIRECT("'"&E$1&"'!AP189") -> 4.1166667 | F28: =INDIRECT("'"&F$1&"'!AP189") -> 2.4766667 | G28: =INDIRECT("'"&G$1&"'!AP189") -> 3.1833333 | H28: =INDIRECT("'"&H$1&"'!AP189") -> -0.49666667 | I28: =INDIRECT("'"&I$1&"'!AP189") -> 0.6
C29: 同比2019 | D29: =INDIRECT("'"&D$1&"'!AQ189") -> 1.5333333 | E29: =INDIRECT("'"&E$1&"'!AQ189") -> 3.38 | F29: =INDIRECT("'"&F$1&"'!AQ189") -> 3.5133333 | G29: =INDIRECT("'"&G$1&"'!AQ189") -> 2.6233333 | H29: =INDIRECT("'"&H$1&"'!AQ189") -> -1.0333333 | I29: =INDIRECT("'"&I$1&"'!AQ189") -> -1.5433333
B30: 国际 | C30: 国际 | D30: 中国国航 | E30: 中国东航 | F30: 南方航空 | G30: 吉祥航空 | H30: 春秋航空 | I30: 海航控股
B31: ASK（百万座公里） | C31: 当期值 | D31: =INDIRECT("'"&D$1&"'!H189") -> 26241.9 | E31: =INDIRECT("'"&E$1&"'!H189") -> 25133.25 | F31: =INDIRECT("'"&F$1&"'!H189") -> 24114.02 | G31: =INDIRECT("'"&G$1&"'!H189") -> 4093.5049 | H31: =INDIRECT("'"&H$1&"'!H189") -> 2889.3836 | I31: =INDIRECT("'"&I$1&"'!H189") -> 9141.59
C32: 同比2024 | D32: =INDIRECT("'"&D$1&"'!I189") -> 0.12376348 | E32: =INDIRECT("'"&E$1&"'!I189") -> 0.20299451 | F32: =INDIRECT("'"&F$1&"'!I189") -> 0.19071996 | G32: =INDIRECT("'"&G$1&"'!I189") -> 0.52230204 | H32: =INDIRECT("'"&H$1&"'!I189") -> 0.18881275 | I32: =INDIRECT("'"&I$1&"'!I189") -> 0.52388279
C33: 同比2019 | D33: =INDIRECT("'"&D$1&"'!J189") -> -0.072081724 | E33: =INDIRECT("'"&E$1&"'!J189") -> 0.12346806 | F33: =INDIRECT("'"&F$1&"'!J189") -> -0.046055081 | G33: =INDIRECT("'"&G$1&"'!J189") -> 1.9097359 | H33: =INDIRECT("'"&H$1&"'!J189") -> -0.11400815 | I33: =INDIRECT("'"&I$1&"'!J189") -> -0.26511478
B34: RPK（百万客公里） | C34: 当期值 | D34: =INDIRECT("'"&D$1&"'!T189") -> 20074 | E34: =INDIRECT("'"&E$1&"'!T189") -> 20845.44 | F34: =INDIRECT("'"&F$1&"'!T189") -> 20309.02 | G34: =INDIRECT("'"&G$1&"'!T189") -> 3314.4366 | H34: =INDIRECT("'"&H$1&"'!T189") -> 2521.2752 | I34: =INDIRECT("'"&I$1&"'!T189") -> 6558.32
C35: 同比2024 | D35: =INDIRECT("'"&D$1&"'!U189") -> 0.14178132 | E35: =INDIRECT("'"&E$1&"'!U189") -> 0.25620269 | F35: =INDIRECT("'"&F$1&"'!U189") -> 0.22478368 | G35: =INDIRECT("'"&G$1&"'!U189") -> 0.61312514 | H35: =INDIRECT("'"&H$1&"'!U189") -> 0.14946759 | I35: =INDIRECT("'"&I$1&"'!U189") -> 0.52553128
C36: 同比2019 | D36: =INDIRECT("'"&D$1&"'!V189") -> -0.095777985 | E36: =INDIRECT("'"&E$1&"'!V189") -> 0.14937286 | F36: =INDIRECT("'"&F$1&"'!V189") -> -0.023417473 | G36: =INDIRECT("'"&G$1&"'!V189") -> 1.8280335 | H36: =INDIRECT("'"&H$1&"'!V189") -> -0.13167513 | I36: =INDIRECT("'"&I$1&"'!V189") -> -0.25906327
B37: 旅客运输量（千人） | C37: 当期值 | D37: =INDIRECT("'"&D$1&"'!AF189") -> 4540.1 | E37: =INDIRECT("'"&E$1&"'!AF189") -> 5045.27 | F37: =INDIRECT("'"&F$1&"'!AF189") -> 5068.49 | G37: =INDIRECT("'"&G$1&"'!AF189") -> 1044.5 | H37: =INDIRECT("'"&H$1&"'!AF189") -> 1400.98 | I37: =INDIRECT("'"&I$1&"'!AF189") -> 989.58
C38: 同比2024 | D38: =INDIRECT("'"&D$1&"'!AG189") -> 0.13242043 | E38: =INDIRECT("'"&E$1&"'!AG189") -> 0.22804067 | F38: =INDIRECT("'"&F$1&"'!AG189") -> 0.22278729 | G38: =INDIRECT("'"&G$1&"'!AG189") -> 0.40979093 | H38: =INDIRECT("'"&H$1&"'!AG189") -> 0.2902388 | I38: =INDIRECT("'"&I$1&"'!AG189") -> 0.54662957
C39: 同比2019 | D39: =INDIRECT("'"&D$1&"'!AH189") -> 0.059162487 | E39: =INDIRECT("'"&E$1&"'!AH189") -> 0.16480201 | F39: =INDIRECT("'"&F$1&"'!AH189") -> 0.033409248 | G39: =INDIRECT("'"&G$1&"'!AH189") -> 0.83894083 | H39: =INDIRECT("'"&H$1&"'!AH189") -> 0.11642547 | I39: =INDIRECT("'"&I$1&"'!AH189") -> -0.29279344
B40: 客座率（%） | C40: 当期值 | D40: =INDIRECT("'"&D$1&"'!AR189") -> 76.5 | E40: =INDIRECT("'"&E$1&"'!AR189") -> 82.95 | F40: =INDIRECT("'"&F$1&"'!AR189") -> 84.213333 | G40: =INDIRECT("'"&G$1&"'!AR189") -> 80.996667 | H40: =INDIRECT("'"&H$1&"'!AR189") -> 87.29 | I40: =INDIRECT("'"&I$1&"'!AR189") -> 71.753333
C41: 同比2024 | D41: =INDIRECT("'"&D$1&"'!AS189") -> 1.1666667 | E41: =INDIRECT("'"&E$1&"'!AS189") -> 3.51 | F41: =INDIRECT("'"&F$1&"'!AS189") -> 2.3133333 | G41: =INDIRECT("'"&G$1&"'!AS189") -> 4.5033333 | H41: =INDIRECT("'"&H$1&"'!AS189") -> -2.99 | I41: =INDIRECT("'"&I$1&"'!AS189") -> 0.14333333
...

Sheet 中国国航
A1: 指标名称 | B1: 可用座公里（百万） | C1: 同比上年 | D1: 同比19 | E1: 可用座公里:国内 | F1: 同比上年 | G1: 同比19 | H1: 可用座公里:国际 | I1: 同比上年 | J1: 同比19 | K1: 可用座公里:地区 | L1: 同比上年 | M1: 同比19 | N1: 收入客公里（百万） | O1: 同比上年 | P1: 同比19 | Q1: 收入客公里:国内 | R1: 同比上年 | S1: 同比19 | T1: 收入客公里:国际 | U1: 同比上年 | V1: 同比19 | W1: 收入客公里:地区 | X1: 同比上年 | Y1: 同比19 | Z1: 客运量（千人次） | AA1: 同比上年 | AB1: 同比19 | AC1: 客运量:国内 | AD1: 同比上年 | AE1: 同比19 | AF1: 客运量:国际 | AG1: 同比上年 | AH1: 同比19 | AI1: 客运量:地区 | AJ1: 同比上年 | AK1: 同比19 | AL1: 客座率 | AM1: 同比上年 | AN1: 同比19 | AO1: 客座率:国内 | AP1: 同比上年 | AQ1: 同比19 | AR1: 客座率:国际 | AS1: 同比上年 | AT1: 同比19 | AU1: 客座率:地区 | AV1: 同比上年 | AW1: 同比19 | AX1: 运营飞机数 | AY1: 同比上年 | AZ1: 同比19
A2: 频率 | B2: 月 | E2: 月 | H2: 月 | K2: 月 | N2: 月 | Q2: 月 | T2: 月 | W2: 月 | Z2: 月 | AC2: 月 | AF2: 月 | AI2: 月 | AL2: 月 | AO2: 月 | AR2: 月 | AU2: 月
B3: ASK | E3: Domestic | H3: International | K3: Regional | N3: RPK | Q3: Domestic | T3: International | W3: Regional | Z3: Pax volume | AC3: Domestic | AF3: International | AI3: Regional | AL3: PLF | AO3: Domestic | AR3: International | AU3: Regional
A4: 41670 | B4: =国航自动更新!B124 -> 15893.3 | E4: =国航自动更新!C124 -> 10507.9 | H4: =国航自动更新!D124 -> 4578.3 | K4: =国航自动更新!E124 -> 807.2 | N4: =国航自动更新!F124 -> 12895.9 | Q4: =国航自动更新!G124 -> 8503.7 | T4: =国航自动更新!H124 -> 3791.1 | W4: =国航自动更新!I124 -> 601.1 | Z4: =国航自动更新!J124 -> 6853.3 | AC4: =国航自动更新!K124 -> 5781.5 | AF4: =国航自动更新!L124 -> 705.9 | AI4: =国航自动更新!M124 -> 365.9 | AL4: =国航自动更新!N124 -> 81.1 | AO4: =国航自动更新!O124 -> 80.9 | AR4: =国航自动更新!P124 -> 82.8 | AU4: =国航自动更新!Q124 -> 74.5 | AX4: =国航自动更新!R124 -> 0
A5: 41698 | B5: =国航自动更新!B125 -> 14641.1 | E5: =国航自动更新!C125 -> 9841.5 | H5: =国航自动更新!D125 -> 4067 | K5: =国航自动更新!E125 -> 732.5 | N5: =国航自动更新!F125 -> 12424.7 | Q5: =国航自动更新!G125 -> 8596.7 | T5: =国航自动更新!H125 -> 3249.9 | W5: =国航自动更新!I125 -> 578.1 | Z5: =国航自动更新!J125 -> 6775.2 | AC5: =国航自动更新!K125 -> 5782.9 | AF5: =国航自动更新!L125 -> 632.2 | AI5: =国航自动更新!M125 -> 360.1 | AL5: =国航自动更新!N125 -> 84.9 | AO5: =国航自动更新!O125 -> 87.4 | AR5: =国航自动更新!P125 -> 79.9 | AU5: =国航自动更新!Q125 -> 78.9 | AX5: =国航自动更新!R125 -> 0
A6: 41729 | B6: =国航自动更新!B126 -> 15409.7 | E6: =国航自动更新!C126 -> 9999.9 | H6: =国航自动更新!D126 -> 4642 | K6: =国航自动更新!E126 -> 767.8 | N6: =国航自动更新!F126 -> 12242.3 | Q6: =国航自动更新!G126 -> 8071.3 | T6: =国航自动更新!H126 -> 3599.6 | W6: =国航自动更新!I126 -> 571.3 | Z6: =国航自动更新!J126 -> 6549.6 | AC6: =国航自动更新!K126 -> 5489.6 | AF6: =国航自动更新!L126 -> 699.6 | AI6: =国航自动更新!M126 -> 360.3 | AL6: =国航自动更新!N126 -> 79.4 | AO6: =国航自动更新!O126 -> 80.7 | AR6: =国航自动更新!P126 -> 77.5 | AU6: =国航自动更新!Q126 -> 74.4 | AX6: =国航自动更新!R126 -> 0
A7: 41759 | B7: =国航自动更新!B127 -> 15775.9 | E7: =国航自动更新!C127 -> 9921.4 | H7: =国航自动更新!D127 -> 5051.7 | K7: =国航自动更新!E127 -> 802.8 | N7: =国航自动更新!F127 -> 12604.2 | Q7: =国航自动更新!G127 -> 8119.4 | T7: =国航自动更新!H127 -> 3901.1 | W7: =国航自动更新!I127 -> 583.7 | Z7: =国航自动更新!J127 -> 6752.9 | AC7: =国航自动更新!K127 -> 5635 | AF7: =国航自动更新!L127 -> 747.2 | AI7: =国航自动更新!M127 -> 370.7 | AL7: =国航自动更新!N127 -> 79.9 | AO7: =国航自动更新!O127 -> 81.8 | AR7: =国航自动更新!P127 -> 77.2 | AU7: =国航自动更新!Q127 -> 72.7 | AX7: =国航自动更新!R127 -> 0
A8: 41790 | B8: =国航自动更新!B128 -> 15695.8 | E8: =国航自动更新!C128 -> 9695.6 | H8: =国航自动更新!D128 -> 5198.1 | K8: =国航自动更新!E128 -> 802 | N8: =国航自动更新!F128 -> 12379.5 | Q8: =国航自动更新!G128 -> 7878 | T8: =国航自动更新!H128 -> 3944.8 | W8: =国航自动更新!I128 -> 556.7 | Z8: =国航自动更新!J128 -> 6603.1 | AC8: =国航自动更新!K128 -> 5522.3 | AF8: =国航自动更新!L128 -> 727.6 | AI8: =国航自动更新!M128 -> 353.2 | AL8: =国航自动更新!N128 -> 78.9 | AO8: =国航自动更新!O128 -> 81.3 | AR8: =国航自动更新!P128 -> 75.9 | AU8: =国航自动更新!Q128 -> 69.4 | AX8: =国航自动更新!R128 -> 0
A9: 41820 | B9: =国航自动更新!B129 -> 15713.2 | E9: =国航自动更新!C129 -> 9718.4 | H9: =国航自动更新!D129 -> 5225.7 | K9: =国航自动更新!E129 -> 769 | N9: =国航自动更新!F129 -> 12507.3 | Q9: =国航自动更新!G129 -> 7841.5 | T9: =国航自动更新!H129 -> 4113 | W9: =国航自动更新!I129 -> 552.7 | Z9: =国航自动更新!J129 -> 6610.2 | AC9: =国航自动更新!K129 -> 5505.5 | AF9: =国航自动更新!L129 -> 751.2 | AI9: =国航自动更新!M129 -> 353.6 | AL9: =国航自动更新!N129 -> 79.6 | AO9: =国航自动更新!O129 -> 80.7 | AR9: =国航自动更新!P129 -> 78.7 | AU9: =国航自动更新!Q129 -> 71.9 | AX9: =国航自动更新!R129 -> 0
A10: 41851 | B10: =国航自动更新!B130 -> 16866.3 | E10: =国航自动更新!C130 -> 10579.6 | H10: =国航自动更新!D130 -> 5491.8 | K10: =国航自动更新!E130 -> 794.9 | N10: =国航自动更新!F130 -> 13650.5 | Q10: =国航自动更新!G130 -> 8602.6 | T10: =国航自动更新!H130 -> 4433.2 | W10: =国航自动更新!I130 -> 614.6 | Z10: =国航自动更新!J130 -> 7341 | AC10: =国航自动更新!K130 -> 6094.6 | AF10: =国航自动更新!L130 -> 853.4 | AI10: =国航自动更新!M130 -> 393 | AL10: =国航自动更新!N130 -> 80.9 | AO10: =国航自动更新!O130 -> 81.3 | AR10: =国航自动更新!P130 -> 80.7 | AU10: =国航自动更新!Q130 -> 77.3 | AX10: =国航自动更新!R130 -> 0
A11: 41882 | B11: =国航自动更新!B131 -> 17452.5 | E11: =国航自动更新!C131 -> 11056.2 | H11: =国航自动更新!D131 -> 5563.2 | K11: =国航自动更新!E131 -> 833.1 | N11: =国航自动更新!F131 -> 14335 | Q11: =国航自动更新!G131 -> 9000.2 | T11: =国航自动更新!H131 -> 4689.8 | W11: =国航自动更新!I131 -> 644.9 | Z11: =国航自动更新!J131 -> 7711.6 | AC11: =国航自动更新!K131 -> 6374.5 | AF11: =国航自动更新!L131 -> 929.4 | AI11: =国航自动更新!M131 -> 407.7 | AL11: =国航自动更新!N131 -> 82.1 | AO11: =国航自动更新!O131 -> 81.4 | AR11: =国航自动更新!P131 -> 84.3 | AU11: =国航自动更新!Q131 -> 77.4 | AX11: =国航自动更新!R131 -> 0
A12: 41912 | B12: =国航自动更新!B132 -> 16300 | E12: =国航自动更新!C132 -> 10093.6 | H12: =国航自动更新!D132 -> 5415.6 | K12: =国航自动更新!E132 -> 790.9 | N12: =国航自动更新!F132 -> 12944.4 | Q12: =国航自动更新!G132 -> 8151.6 | T12: =国航自动更新!H132 -> 4221.4 | W12: =国航自动更新!I132 -> 571.4 | Z12: =国航自动更新!J132 -> 6893.3 | AC12: =国航自动更新!K132 -> 5717.2 | AF12: =国航自动更新!L132 -> 823.1 | AI12: =国航自动更新!M132 -> 353.1 | AL12: =国航自动更新!N132 -> 79.4 | AO12: =国航自动更新!O132 -> 80.8 | AR12: =国航自动更新!P132 -> 77.9 | AU12: =国航自动更新!Q132 -> 72.2 | AX12: =国航自动更新!R132 -> 0
A13: 41943 | B13: =国航自动更新!B133 -> 16879.2 | E13: =国航自动更新!C133 -> 10461.8 | H13: =国航自动更新!D133 -> 5589.6 | K13: =国航自动更新!E133 -> 827.8 | N13: =国航自动更新!F133 -> 13266.9 | Q13: =国航自动更新!G133 -> 8560.5 | T13: =国航自动更新!H133 -> 4116.1 | W13: =国航自动更新!I133 -> 590.3 | Z13: =国航自动更新!J133 -> 7229.5 | AC13: =国航自动更新!K133 -> 6032.9 | AF13: =国航自动更新!L133 -> 827.4 | AI13: =国航自动更新!M133 -> 369.2 | AL13: =国航自动更新!N133 -> 78.6 | AO13: =国航自动更新!O133 -> 81.8 | AR13: =国航自动更新!P133 -> 73.6 | AU13: =国航自动更新!Q133 -> 71.3 | AX13: =国航自动更新!R133 -> 0
A14: 41973 | B14: =国航自动更新!B134 -> 16297.3 | E14: =国航自动更新!C134 -> 10624.9 | H14: =国航自动更新!D134 -> 4880 | K14: =国航自动更新!E134 -> 792.4 | N14: =国航自动更新!F134 -> 12681.5 | Q14: =国航自动更新!G134 -> 8500.5 | T14: =国航自动更新!H134 -> 3611.1 | W14: =国航自动更新!I134 -> 569.9 | Z14: =国航自动更新!J134 -> 6922.8 | AC14: =国航自动更新!K134 -> 5809.3 | AF14: =国航自动更新!L134 -> 755.6 | AI14: =国航自动更新!M134 -> 357.8 | AL14: =国航自动更新!N134 -> 77.8 | AO14: =国航自动更新!O134 -> 80 | AR14: =国航自动更新!P134 -> 74 | AU14: =国航自动更新!Q134 -> 71.9 | AX14: =国航自动更新!R134 -> 0
A15: 42004 | B15: =国航自动更新!B135 -> 16671 | E15: =国航自动更新!C135 -> 10617.9 | H15: =国航自动更新!D135 -> 5248.2 | K15: =国航自动更新!E135 -> 804.8 | N15: =国航自动更新!F135 -> 12750.5 | Q15: =国航自动更新!G135 -> 8273 | T15: =国航自动更新!H135 -> 3912.2 | W15: =国航自动更新!I135 -> 565.4 | Z15: =国航自动更新!J135 -> 6765.8 | AC15: =国航自动更新!K135 -> 5624.9 | AF15: =国航自动更新!L135 -> 784.3 | AI15: =国航自动更新!M135 -> 356.6 | AL15: =国航自动更新!N135 -> 76.5 | AO15: =国航自动更新!O135 -> 77.9 | AR15: =国航自动更新!P135 -> 74.5 | AU15: =国航自动更新!Q135 -> 70.2 | AX15: =国航自动更新!R135 -> 0
A16: 42035 | B16: =国航自动更新!B136 -> 16712.4 | C16: =B16/B4-1 -> 0.05153744 | E16: =国航自动更新!C136 -> 10693.3 | F16: =E16/E4-1 -> 0.017643868 | H16: =国航自动更新!D136 -> 5237.4 | I16: =H16/H4-1 -> 0.14396173 | K16: =国航自动更新!E136 -> 781.7 | L16: =K16/K4-1 -> -0.031590684 | N16: =国航自动更新!F136 -> 12777.5 | O16: =N16/N4-1 -> -0.0091812126 | Q16: =国航自动更新!G136 -> 8405 | R16: =Q16/Q4-1 -> -0.011606712 | T16: =国航自动更新!H136 -> 3865.1 | U16: =T16/T4-1 -> 0.019519401 | W16: =国航自动更新!I136 -> 507.4 | X16: =W16/W4-1 -> -0.15588089 | Z16: =国航自动更新!J136 -> 6731.1 | AA16: =Z16/Z4-1 -> -0.017830826 | AC16: =国航自动更新!K136 -> 5638 | AD16: =AC16/AC4-1 -> -0.024820548 | AF16: =国航自动更新!L136 -> 776.8 | AG16: =AF16/AF4-1 -> 0.10043916 | AI16: =国航自动更新!M136 -> 316.3 | AJ16: =AI16/AI4-1 -> -0.13555616 | AL16: =国航自动更新!N136 -> 76.5 | AM16: =AL16-AL4 -> -4.6 | AO16: =国航自动更新!O136 -> 78.6 | AP16: =AO16-AO4 -> -2.3 | AR16: =国航自动更新!P136 -> 73.8 | AS16: =AR16-AR4 -> -9 | AU16: =国航自动更新!Q136 -> 64.9 | AV16: =AU16-AU4 -> -9.6 | AX16: =国航自动更新!R136 -> 0
A17: 42063 | B17: =国航自动更新!B137 -> 16429.4 | C17: =B17/B5-1 -> 0.12214246 | E17: =国航自动更新!C137 -> 10662.6 | F17: =E17/E5-1 -> 0.083432404 | H17: =国航自动更新!D137 -> 4930.3 | I17: =H17/H5-1 -> 0.21226949 | K17: =国航自动更新!E137 -> 836.5 | L17: =K17/K5-1 -> 0.14197952 | N17: =国航自动更新!F137 -> 13557.3 | O17: =N17/N5-1 -> 0.091157131 | Q17: =国航自动更新!G137 -> 8930.2 | R17: =Q17/Q5-1 -> 0.038793956 | T17: =国航自动更新!H137 -> 3967.9 | U17: =T17/T5-1 -> 0.22092987 | W17: =国航自动更新!I137 -> 659.2 | X17: =W17/W5-1 -> 0.14028715 | Z17: =国航自动更新!J137 -> 7269.7 | AA17: =Z17/Z5-1 -> 0.072986775 | AC17: =国航自动更新!K137 -> 6004 | AD17: =AC17/AC5-1 -> 0.038233412 | AF17: =国航自动更新!L137 -> 851.7 | AG17: =AF17/AF5-1 -> 0.34720025 | AI17: =国航自动更新!M137 -> 414 | AJ17: =AI17/AI5-1 -> 0.14968064 | AL17: =国航自动更新!N137 -> 82.5 | AM17: =AL17-AL5 -> -2.4 | AO17: =国航自动更新!O137 -> 83.8 | AP17: =AO17-AO5 -> -3.6 | AR17: =国航自动更新!P137 -> 80.5 | AS17: =AR17-AR5 -> 0.6 | AU17: =国航自动更新!Q137 -> 78.8 | AV17: =AU17-AU5 -> -0.1 | AX17: =国航自动更新!R137 -> 0
A18: 42094 | B18: =国航自动更新!B138 -> 17489.4 | C18: =B18/B6-1 -> 0.13496045 | E18: =国航自动更新!C138 -> 11356.8 | F18: =E18/E6-1 -> 0.13569136 | H18: =国航自动更新!D138 -> 5326 | I18: =H18/H6-1 -> 0.14735028 | K18: =国航自动更新!E138 -> 806.6 | L18: =K18/K6-1 -> 0.050533993 | N18: =国航自动更新!F138 -> 14287.2 | O18: =N18/N6-1 -> 0.16703561 | Q18: =国航自动更新!G138 -> 9631.2 | R18: =Q18/Q6-1 -> 0.19326503 | T18: =国航自动更新!H138 -> 4136 | U18: =T18/T6-1 -> 0.14901656 | W18: =国航自动更新!I138 -> 520 | X18: =W18/W6-1 -> -0.089795204 | Z18: =国航自动更新!J138 -> 7712 | AA18: =Z18/Z6-1 -> 0.17747649 | AC18: =国航自动更新!K138 -> 6520.6 | AD18: =AC18/AC6-1 -> 0.18780968 | AF18: =国航自动更新!L138 -> 860.8 | AG18: =AF18/AF6-1 -> 0.23041738 | AI18: =国航自动更新!M138 -> 330.7 | AJ18: =AI18/AI6-1 -> -0.082153761 | AL18: =国航自动更新!N138 -> 81.7 | AM18: =AL18-AL6 -> 2.3 | AO18: =国航自动更新!O138 -> 84.8 | AP18: =AO18-AO6 -> 4.1 | AR18: =国航自动更新!P138 -> 77.7 | AS18: =AR18-AR6 -> 0.2 | AU18: =国航自动更新!Q138 -> 64.5 | AV18: =AU18-AU6 -> -9.9 | AX18: =国航自动更新!R138 -> 0
A19: 42124 | B19: =国航自动更新!B139 -> 17196.9 | C19: =B19/B7-1 -> 0.0900741 | E19: =国航自动更新!C139 -> 10712 | F19: =E19/E7-1 -> 0.079686335 | H19: =国航自动更新!D139 -> 5664.8 | I19: =H19/H7-1 -> 0.12136509 | K19: =国航自动更新!E139 -> 820.1 | L19: =K19/K7-1 -> 0.021549576 | N19: =国航自动更新!F139 -> 13793.3 | O19: =N19/N7-1 -> 0.094341569 | Q19: =国航自动更新!G139 -> 8867.2 | R19: =Q19/Q7-1 -> 0.092100402 | T19: =国航自动更新!H139 -> 4362.8 | U19: =T19/T7-1 -> 0.11835123 | W19: =国航自动更新!I139 -> 563.2 | X19: =W19/W7-1 -> -0.035120781 | Z19: =国航自动更新!J139 -> 7404.9 | AA19: =Z19/Z7-1 -> 0.096551111 | AC19: =国航自动更新!K139 -> 6126.5 | AD19: =AC19/AC7-1 -> 0.087222715 | AF19: =国航自动更新!L139 -> 916.3 | AG19: =AF19/AF7-1 -> 0.22631156 | AI19: =国航自动更新!M139 -> 362 | AJ19: =AI19/AI7-1 -> -0.023469112 | AL19: =国航自动更新!N139 -> 80.2 | AM19: =AL19-AL7 -> 0.3 | AO19: =国航自动更新!O139 -> 82.8 | AP19: =AO19-AO7 -> 1 | AR19: =国航自动更新!P139 -> 77 | AS19: =AR19-AR7 -> -0.2 | AU19: =国航自动更新!Q139 -> 68.7 | AV19: =AU19-AU7 -> -4 | AX19: =国航自动更新!R139 -> 0
A20: 42155 | B20: =国航自动更新!B140 -> 17706.1 | C20: =B20/B8-1 -> 0.12807885 | E20: =国航自动更新!C140 -> 10917 | F20: =E20/E8-1 -> 0.12597467 | H20: =国航自动更新!D140 -> 5972.3 | I20: =H20/H8-1 -> 0.14893904 | K20: =国航自动更新!E140 -> 816.8 | L20: =K20/K8-1 -> 0.018453865 | N20: =国航自动更新!F140 -> 13925.2 | O20: =N20/N8-1 -> 0.12485965 | Q20: =国航自动更新!G140 -> 8835.3 | R20: =Q20/Q8-1 -> 0.12151561 | T20: =国航自动更新!H140 -> 4519.3 | U20: =T20/T8-1 -> 0.14563476 | W20: =国航自动更新!I140 -> 570.5 | X20: =W20/W8-1 -> 0.024788935 | Z20: =国航自动更新!J140 -> 7404.3 | AA20: =Z20/Z8-1 -> 0.12133695 | AC20: =国航自动更新!K140 -> 6111.5 | AD20: =AC20/AC8-1 -> 0.10669467 | AF20: =国航自动更新!L140 -> 924.5 | AG20: =AF20/AF8-1 -> 0.27061572 | AI20: =国航自动更新!M140 -> 368.4 | AJ20: =AI20/AI8-1 -> 0.043035108 | AL20: =国航自动更新!N140 -> 78.6 | AM20: =AL20-AL8 -> -0.3 | AO20: =国航自动更新!O140 -> 80.9 | AP20: =AO20-AO8 -> -0.4 | AR20: =国航自动更新!P140 -> 75.7 | AS20: =AR20-AR8 -> -0.2 | AU20: =国航自动更新!Q140 -> 69.9 | AV20: =AU20-AU8 -> 0.5 | AX20: =国航自动更新!R140 -> 0
A21: 42185 | B21: =国航自动更新!B141 -> 17347.5 | C21: =B21/B9-1 -> 0.1040081 | E21: =国航自动更新!C141 -> 10579.5 | F21: =E21/E9-1 -> 0.08860512 | H21: =国航自动更新!D141 -> 5980.8 | I21: =H21/H9-1 -> 0.14449739 | K21: =国航自动更新!E141 -> 787.2 | L21: =K21/K9-1 -> 0.0236671 | N21: =国航自动更新!F141 -> 13835.7 | O21: =N21/N9-1 -> 0.10620997 | Q21: =国航自动更新!G141 -> 8558.5 | R21: =Q21/Q9-1 -> 0.091436587 | T21: =国航自动更新!H141 -> 4737.5 | U21: =T21/T9-1 -> 0.15183564 | W21: =国航自动更新!I141 -> 539.8 | X21: =W21/W9-1 -> -0.023339967 | Z21: =国航自动更新!J141 -> 7151.4 | AA21: =Z21/Z9-1 -> 0.081873468 | AC21: =国航自动更新!K141 -> 5927.7 | AD21: =AC21/AC9-1 -> 0.076686949 | AF21: =国航自动更新!L141 -> 876.2 | AG21: =AF21/AF9-1 -> 0.16640043 | AI21: =国航自动更新!M141 -> 347.5 | AJ21: =AI21/AI9-1 -> -0.017251131 | AL21: =国航自动更新!N141 -> 79.8 | AM21: =AL21-AL9 -> 0.2 | AO21: =国航自动更新!O141 -> 80.9 | AP21: =AO21-AO9 -> 0.2 | AR21: =国航自动更新!P141 -> 79.2 | AS21: =AR21-AR9 -> 0.5 | AU21: =国航自动更新!Q141 -> 68.6 | AV21: =AU21-AU9 -> -3.3 | AX21: =国航自动更新!R141 -> 0
A22: 42216 | B22: =国航自动更新!B142 -> 18967.9 | C22: =B22/B10-1 -> 0.1246035 | E22: =国航自动更新!C142 -> 11785.4 | F22: =E22/E10-1 -> 0.11397406 | H22: =国航自动更新!D142 -> 6380.5 | I22: =H22/H10-1 -> 0.16182308 | K22: =国航自动更新!E142 -> 801.9 | L22: =K22/K10-1 -> 0.0088061391 | N22: =国航自动更新!F142 -> 15438.8 | O22: =N22/N10-1 -> 0.13100619 | Q22: =国航自动更新!G142 -> 9626.8 | R22: =Q22/Q10-1 -> 0.11905703 | T22: =国航自动更新!H142 -> 5236 | U22: =T22/T10-1 -> 0.18108815 | W22: =国航自动更新!I142 -> 576 | X22: =W22/W10-1 -> -0.062805076 | Z22: =国航自动更新!J142 -> 8008.7 | AA22: =Z22/Z10-1 -> 0.090954911 | AC22: =国航自动更新!K142 -> 6688.6 | AD22: =AC22/AC10-1 -> 0.097463328 | AF22: =国航自动更新!L142 -> 945.3 | AG22: =AF22/AF10-1 -> 0.1076869 | AI22: =国航自动更新!M142 -> 374.8 | AJ22: =AI22/AI10-1 -> -0.046310433 | AL22: =国航自动更新!N142 -> 81.4 | AM22: =AL22-AL10 -> 0.5 | AO22: =国航自动更新!O142 -> 81.7 | AP22: =AO22-AO10 -> 0.4 | AR22: =国航自动更新!P142 -> 82.1 | AS22: =AR22-AR10 -> 1.4 | AU22: =国航自动更新!Q142 -> 71.8 | AV22: =AU22-AU10 -> -5.5 | AX22: =国航自动更新!R142 -> 0
A23: 42247 | B23: =国航自动更新!B143 -> 19454.8 | C23: =B23/B11-1 -> 0.11472855 | E23: =国航自动更新!C143 -> 11961.2 | F23: =E23/E11-1 -> 0.081854525 | H23: =国航自动更新!D143 -> 6654.9 | I23: =H23/H11-1 -> 0.19623598 | K23: =国航自动更新!E143 -> 838.7 | L23: =K23/K11-1 -> 0.0067218821 | N23: =国航自动更新!F143 -> 16405.8 | O23: =N23/N11-1 -> 0.14445762 | Q23: =国航自动更新!G143 -> 10024.9 | R23: =Q23/Q11-1 -> 0.11385303 | T23: =国航自动更新!H143 -> 5723.5 | U23: =T23/T11-1 -> 0.22041452 | W23: =国航自动更新!I143 -> 657.5 | X23: =W23/W11-1 -> 0.019537913 | Z23: =国航自动更新!J143 -> 8410.4 | AA23: =Z23/Z11-1 -> 0.090616733 | AC23: =国航自动更新!K143 -> 6918.6 | AD23: =AC23/AC11-1 -> 0.085355714 | AF23: =国航自动更新!L143 -> 1068.1 | AG23: =AF23/AF11-1 -> 0.14923607 | AI23: =国航自动更新!M143 -> 423.7 | AJ23: =AI23/AI11-1 -> 0.039244543 | AL23: =国航自动更新!N143 -> 84.3 | AM23: =AL23-AL11 -> 2.2 | AO23: =国航自动更新!O143 -> 83.8 | AP23: =AO23-AO11 -> 2.4 | AR23: =国航自动更新!P143 -> 86 | AS23: =AR23-AR11 -> 1.7 | AU23: =国航自动更新!Q143 -> 78.4 | AV23: =AU23-AU11 -> 1 | AX23: =国航自动更新!R143 -> 0
A24: 42277 | B24: =国航自动更新!B144 -> 18209.7 | C24: =B24/B12-1 -> 0.11715951 | E24: =国航自动更新!C144 -> 11091.8 | F24: =E24/E12-1 -> 0.098894349 | H24: =国航自动更新!D144 -> 6320 | I24: =H24/H12-1 -> 0.16699904 | K24: =国航自动更新!E144 -> 797.9 | L24: =K24/K12-1 -> 0.0088506764 | N24: =国航自动更新!F144 -> 14442.7 | O24: =N24/N12-1 -> 0.1157489 | Q24: =国航自动更新!G144 -> 9071.7 | R24: =Q24/Q12-1 -> 0.11287355 | T24: =国航自动更新!H144 -> 4822.9 | U24: =T24/T12-1 -> 0.14248827 | W24: =国航自动更新!I144 -> 548.1 | X24: =W24/W12-1 -> -0.040777039 | Z24: =国航自动更新!J144 -> 7496.6 | AA24: =Z24/Z12-1 -> 0.087519766 | AC24: =国航自动更新!K144 -> 6220.6 | AD24: =AC24/AC12-1 -> 0.088050094 | AF24: =国航自动更新!L144 -> 925.2 | AG24: =AF24/AF12-1 -> 0.12404325 | AI24: =国航自动更新!M144 -> 350.8 | AJ24: =AI24/AI12-1 -> -0.0065137355 | AL24: =国航自动更新!N144 -> 79.3 | AM24: =AL24-AL12 -> -0.1 | AO24: =国航自动更新!O144 -> 81.8 | AP24: =AO24-AO12 -> 1 | AR24: =国航自动更新!P144 -> 76.3 | AS24: =AR24-AR12 -> -1.6 | AU24: =国航自动更新!Q144 -> 68.7 | AV24: =AU24-AU12 -> -3.5 | AX24: =国航自动更新!R144 -> 0
A25: 42308 | B25: =国航自动更新!B145 -> 18997.1 | C25: =B25/B13-1 -> 0.12547396 | E25: =国航自动更新!C145 -> 11330.3 | F25: =E25/E13-1 -> 0.083016307 | H25: =国航自动更新!D145 -> 6815.7 | I25: =H25/H13-1 -> 0.2193538 | K25: =国航自动更新!E145 -> 851.1 | L25: =K25/K13-1 -> 0.028146895 | N25: =国航自动更新!F145 -> 15196.7 | O25: =N25/N13-1 -> 0.14545975 | Q25: =国航自动更新!G145 -> 9515.8 | R25: =Q25/Q13-1 -> 0.11159395 | T25: =国航自动更新!H145 -> 5066.2 | U25: =T25/T13-1 -> 0.2308253 | W25: =国航自动更新!I145 -> 614.7 | X25: =W25/W13-1 -> 0.041334914 | Z25: =国航自动更新!J145 -> 7940.3 | AA25: =Z25/Z13-1 -> 0.098319386 | AC25: =国航自动更新!K145 -> 6551.3 | AD25: =AC25/AC13-1 -> 0.085928824 | AF25: =国航自动更新!L145 -> 998.6 | AG25: =AF25/AF13-1 -> 0.20691322 | AI25: =国航自动更新!M145 -> 390.4 | AJ25: =AI25/AI13-1 -> 0.057421452 | AL25: =国航自动更新!N145 -> 80 | AM25: =AL25-AL13 -> 1.4 | AO25: =国航自动更新!O145 -> 84 | AP25: =AO25-AO13 -> 2.2 | AR25: =国航自动更新!P145 -> 74.3 | AS25: =AR25-AR13 -> 0.7 | AU25: =国航自动更新!Q145 -> 72.2 | AV25: =AU25-AU13 -> 0.9 | AX25: =国航自动更新!R145 -> 0
A26: 42338 | B26: =国航自动更新!B146 -> 17733.7 | C26: =B26/B14-1 -> 0.088137299 | E26: =国航自动更新!C146 -> 10451.2 | F26: =E26/E14-1 -> -0.016348389 | H26: =国航自动更新!D146 -> 6476.2 | I26: =H26/H14-1 -> 0.32709016 | K26: =国航自动更新!E146 -> 806.3 | L26: =K26/K14-1 -> 0.017541646 | N26: =国航自动更新!F146 -> 13841.5 | O26: =N26/N14-1 -> 0.091471829 | Q26: =国航自动更新!G146 -> 8533.4 | R26: =Q26/Q14-1 -> 0.0038703606 | T26: =国航自动更新!H146 -> 4729.7 | U26: =T26/T14-1 -> 0.30976711 | W26: =国航自动更新!I146 -> 578.4 | X26: =W26/W14-1 -> 0.014914897 | Z26: =国航自动更新!J146 -> 7116.1 | AA26: =Z26/Z14-1 -> 0.027922228 | AC26: =国航自动更新!K146 -> 5807.5 | AD26: =AC26/AC14-1 -> -0.000309848 | AF26: =国航自动更新!L146 -> 944.3 | AG26: =AF26/AF14-1 -> 0.24973531 | AI26: =国航自动更新!M146 -> 364.3 | AJ26: =AI26/AI14-1 -> 0.018166574 | AL26: =国航自动更新!N146 -> 78.1 | AM26: =AL26-AL14 -> 0.3 | AO26: =国航自动更新!O146 -> 81.7 | AP26: =AO26-AO14 -> 1.7 | AR26: =国航自动更新!P146 -> 73 | AS26: =AR26-AR14 -> -1 | AU26: =国航自动更新!Q146 -> 71.7 | AV26: =AU26-AU14 -> -0.2 | AX26: =国航自动更新!R146 -> 0
A27: 42369 | B27: =国航自动更新!B147 -> 18563.2 | C27: =B27/B15-1 -> 0.11350249 | E27: =国航自动更新!C147 -> 10859.2 | F27: =E27/E15-1 -> 0.022725774 | H27: =国航自动更新!D147 -> 6879.5 | I27: =H27/H15-1 -> 0.31083038 | K27: =国航自动更新!E147 -> 824.4 | L27: =K27/K15-1 -> 0.024353877 | N27: =国航自动更新!F147 -> 14194.7 | O27: =N27/N15-1 -> 0.11326615 | Q27: =国航自动更新!G147 -> 8576.3 | R27: =Q27/Q15-1 -> 0.036661429 | T27: =国航自动更新!H147 -> 5030.9 | U27: =T27/T15-1 -> 0.28595164 | W27: =国航自动更新!I147 -> 587.4 | X27: =W27/W15-1 -> 0.038910506 | Z27: =国航自动更新!J147 -> 7162.2 | AA27: =Z27/Z15-1 -> 0.058588785 | AC27: =国航自动更新!K147 -> 5807.8 | AD27: =AC27/AC15-1 -> 0.032516134 | AF27: =国航自动更新!L147 -> 984.9 | AG27: =AF27/AF15-1 -> 0.25576948 | AI27: =国航自动更新!M147 -> 369.6 | AJ27: =AI27/AI15-1 -> 0.036455412 | AL27: =国航自动更新!N147 -> 76.5 | AM27: =AL27-AL15 -> 0 | AO27: =国航自动更新!O147 -> 79 | AP27: =AO27-AO15 -> 1.1 | AR27: =国航自动更新!P147 -> 73.1 | AS27: =AR27-AR15 -> -1.4 | AU27: =国航自动更新!Q147 -> 71.3 | AV27: =AU27-AU15 -> 1.1 | AX27: =国航自动更新!R147 -> 0
... A59: 43343 | B59: =国航自动更新!B179 -> 23847.2 | C59: =B59/B47-1 -> 0.09556165 | E59: =国航自动更新!C179 -> 13668 | F59: =E59/E47-1 -> 0.062946199 | H59: =国航自动更新!D179 -> 9313.3 | I59: =H59/H47-1 -> 0.14525153 | K59: =国航自动更新!E179 -> 865.9 | L59: =K59/K47-1 -> 0.11527563 | N59: =国航自动更新!F179 -> 20053.3 | O59: =N59/N47-1 -> 0.11097999 | Q59: =国航自动更新!G179 -> 11802.8 | R59: =Q59/Q47-1 -> 0.092851852 | T59: =国航自动更新!H179 -> 7499.9 | U59: =T59/T47-1 -> 0.13907536 | W59: =国航自动更新!I179 -> 750.7 | X59: =W59/W47-1 -> 0.12751577 | Z59: =国航自动更新!J179 -> 9895.8 | AA59: =Z59/Z47-1 -> 0.09432919 | AC59: =国航自动更新!K179 -> 7990.4 | AD59: =AC59/AC47-1 -> 0.083737963 | AF59: =国航自动更新!L179 -> 1424.5 | AG59: =AF59/AF47-1 -> 0.14916102 | AI59: =国航自动更新!M179 -> 480.9 | AJ59: =AI59/AI47-1 -> 0.11785216 | AL59: =国航自动更新!N179 -> 84.1 | AM59: =AL59-AL47 -> 1.2 | AO59: =国航自动更新!O179 -> 86.4 | AP59: =AO59-AO47 -> 2.4 | AR59: =国航自动更新!P179 -> 80.5 | AS59: =AR59-AR47 -> -0.5 | AU59: =国航自动更新!Q179 -> 86.7 | AV59: =AU59-AU47 -> 0.9 | AX59: =国航自动更新!R179 -> 668
A60: 43373 | B60: =国航自动更新!B180 -> 22591.7 | C60: =B60/B48-1 -> 0.062928739 | E60: =国航自动更新!C180 -> 13055.1 | F60: =E60/E48-1 -> 0.03306086 | H60: =国航自动更新!D180 -> 8807.9 | I60: =H60/H48-1 -> 0.1173426 | K60: =国航自动更新!E180 -> 728.8 | L60: =K60/K48-1 -> -0.0070844687 | N60: =国航自动更新!F180 -> 18139.8 | O60: =N60/N48-1 -> 0.068782258 | Q60: =国航自动更新!G180 -> 10723 | R60: =Q60/Q48-1 -> 0.043103532 | T60: =国航自动更新!H180 -> 6829.2 | U60: =T60/T48-1 -> 0.11694089 | W60: =国航自动更新!I180 -> 587.6 | X60: =W60/W48-1 -> 0.015905947 | Z60: =国航自动更新!J180 -> 8911 | AA60: =Z60/Z48-1 -> 0.049044076 | AC60: =国航自动更新!K180 -> 7273.6 | AD60: =AC60/AC48-1 -> 0.037455427 | AF60: =国航自动更新!L180 -> 1260.8 | AG60: =AF60/AF48-1 -> 0.12863665 | AI60: =国航自动更新!M180 -> 376.6 | AJ60: =AI60/AI48-1 -> 0.027838428 | AL60: =国航自动更新!N180 -> 80.3 | AM60: =AL60-AL48 -> 0.4 | AO60: =国航自动更新!O180 -> 82.1 | AP60: =AO60-AO48 -> 0.8 | AR60: =国航自动更新!P180 -> 77.5 | AS60: =AR60-AR48 -> -0.1 | AU60: =国航自动更新!Q180 -> 80.6 | AV60: =AU60-AU48 -> 1.8 | AX60: =国航自动更新!R180 -> 673 | AY60: =AX60/AX48-1 -> 0.046656299
A61: 43404 | B61: =国航自动更新!B181 -> 23619.7 | C61: =B61/B49-1 -> 0.077747561 | E61: =国航自动更新!C181 -> 13920 | F61: =E61/E49-1 -> 0.068927387 | H61: =国航自动更新!D181 -> 8818.4 | I61: =H61/H49-1 -> 0.086518321 | K61: =国航自动更新!E181 -> 881.3 | L61: =K61/K49-1 -> 0.13394236 | N61: =国航自动更新!F181 -> 19129.2 | O61: =N61/N49-1 -> 0.077907881 | Q61: =国航自动更新!G181 -> 11742 | R61: =Q61/Q49-1 -> 0.079009759 | T61: =国航自动更新!H181 -> 6700.6 | U61: =T61/T49-1 -> 0.07322933 | W61: =国航自动更新!I181 -> 686.6 | X61: =W61/W49-1 -> 0.10581414 | Z61: =国航自动更新!J181 -> 9695.7 | AA61: =Z61/Z49-1 -> 0.078906372 | AC61: =国航自动更新!K181 -> 7979.4 | AD61: =AC61/AC49-1 -> 0.073538909 | AF61: =国航自动更新!L181 -> 1287.5 | AG61: =AF61/AF49-1 -> 0.1107756 | AI61: =国航自动更新!M181 -> 428.8 | AJ61: =AI61/AI49-1 -> 0.086119554 | AL61: =国航自动更新!N181 -> 81 | AM61: =AL61-AL49 -> 0 | AO61: =国航自动更新!O181 -> 84.4 | AP61: =AO61-AO49 -> 0.8 | AR61: =国航自动更新!P181 -> 76 | AS61: =AR61-AR49 -> -0.9 | AU61: =国航自动更新!Q181 -> 77.9 | AV61: =AU61-AU49 -> -2 | AX61: =国航自动更新!R181 -> 679 | AY61: =AX61/AX49-1 -> 0.055987558
A62: 43434 | B62: =国航自动更新!B182 -> 22559.6 | C62: =B62/B50-1 -> 0.073770687 | E62: =国航自动更新!C182 -> 13352.9 | F62: =E62/E50-1 -> 0.047097386 | H62: =国航自动更新!D182 -> 8358.8 | I62: =H62/H50-1 -> 0.11498239 | K62: =国航自动更新!E182 -> 848 | L62: =K62/K50-1 -> 0.11490928 | N62: =国航自动更新!F182 -> 17958.2 | O62: =N62/N50-1 -> 0.049861739 | Q62: =国航自动更新!G182 -> 10845.6 | R62: =Q62/Q50-1 -> 0.018500085 | T62: =国航自动更新!H182 -> 6434.5 | U62: =T62/T50-1 -> 0.10440768 | W62: =国航自动更新!I182 -> 678.2 | X62: =W62/W50-1 -> 0.075654243 | Z62: =国航自动更新!J182 -> 9015.7 | AA62: =Z62/Z50-1 -> 0.04002907 | AC62: =国航自动更新!K182 -> 7332.6 | AD62: =AC62/AC50-1 -> 0.024463849 | AF62: =国航自动更新!L182 -> 1260 | AG62: =AF62/AF50-1 -> 0.13482842 | AI62: =国航自动更新!M182 -> 423.2 | AJ62: =AI62/AI50-1 -> 0.055624844 | AL62: =国航自动更新!N182 -> 79.6 | AM62: =AL62-AL50 -> -1.8 | AO62: =国航自动更新!O182 -> 81.2 | AP62: =AO62-AO50 -> -2.3 | AR62: =国航自动更新!P182 -> 77 | AS62: =AR62-AR50 -> -0.7 | AU62: =国航自动更新!Q182 -> 80 | AV62: =AU62-AU50 -> -2.9 | AX62: =国航自动更新!R182 -> 680 | AY62: =AX62/AX50-1 -> 0.052631579
A63: 43465 | B63: =国航自动更新!B183 -> 23351 | C63: =B63/B51-1 -> 0.080684574 | E63: =国航自动更新!C183 -> 13704.8 | F63: =E63/E51-1 -> 0.083554712 | H63: =国航自动更新!D183 -> 8762.9 | I63: =H63/H51-1 -> 0.070212506 | K63: =国航自动更新!E183 -> 883.3 | L63: =K63/K51-1 -> 0.14476413 | N63: =国航自动更新!F183 -> 18354.7 | O63: =N63/N51-1 -> 0.057572527 | Q63: =国航自动更新!G183 -> 10814.5 | R63: =Q63/Q51-1 -> 0.049564238 | T63: =国航自动更新!H183 -> 6821.8 | U63: =T63/T51-1 -> 0.064093965 | W63: =国航自动更新!I183 -> 718.5 | X63: =W63/W51-1 -> 0.12125468 | Z63: =国航自动更新!J183 -> 9040.4 | AA63: =Z63/Z51-1 -> 0.057901142 | AC63: =国航自动更新!K183 -> 7257.6 | AD63: =AC63/AC51-1 -> 0.049635543 | AF63: =国航自动更新!L183 -> 1331.9 | AG63: =AF63/AF51-1 -> 0.092527274 | AI63: =国航自动更新!M183 -> 450.8 | AJ63: =AI63/AI51-1 -> 0.093909245 | AL63: =国航自动更新!N183 -> 78.6 | AM63: =AL63-AL51 -> -1.7 | AO63: =国航自动更新!O183 -> 78.9 | AP63: =AO63-AO51 -> -2.6 | AR63: =国航自动更新!P183 -> 77.8 | AS63: =AR63-AR51 -> -0.5 | AU63: =国航自动更新!Q183 -> 81.3 | AV63: =AU63-AU51 -> -1.7 | AX63: =国航自动更新!R183 -> 684 | AY63: =AX63/AX51-1 -> 0.044274809
A64: 43496 | B64: =国航自动更新!B184 -> 23688.7 | C64: =B64/B52-1 -> 0.071135629 | E64: =国航自动更新!C184 -> 13761.8 | F64: =E64/E52-1 -> 0.056649263 | H64: =国航自动更新!D184 -> 9006.6 | I64: =H64/H52-1 -> 0.08335739 | K64: =国航自动更新!E184 -> 920.4 | L64: =K64/K52-1 -> 0.1831855 | N64: =国航自动更新!F184 -> 18930.6 | O64: =N64/N52-1 -> 0.083711638 | Q64: =国航自动更新!G184 -> 10960.5 | R64: =Q64/Q52-1 -> 0.048199684 | T64: =国航自动更新!H184 -> 7216.3 | U64: =T64/T52-1 -> 0.12842846 | W64: =国航自动更新!I184 -> 753.7 | X64: =W64/W52-1 -> 0.22195201 | Z64: =国航自动更新!J184 -> 9156.5 | AA64: =Z64/Z52-1 -> 0.065911551 | AC64: =国航自动更新!K184 -> 7243.8 | AD64: =AC64/AC52-1 -> 0.037674765 | AF64: =国航自动更新!L184 -> 1441.1 | AG64: =AF64/AF52-1 -> 0.18239252 | AI64: =国航自动更新!M184 -> 471.6 | AJ64: =AI64/AI52-1 -> 0.20706424 | AL64: =国航自动更新!N184 -> 79.9 | AM64: =AL64-AL52 -> 0.9 | AO64: =国航自动更新!O184 -> 79.6 | AP64: =AO64-AO52 -> -0.7 | AR64: =国航自动更新!P184 -> 80.1 | AS64: =AR64-AR52 -> 3.2 | AU64: =国航自动更新!Q184 -> 81.9 | AV64: =AU64-AU52 -> 2.6 | AX64: =国航自动更新!R184 -> 671 | AY64: =AX64/AX52-1 -> 0.024427481
A65: 43524 | B65: =国航自动更新!B185 -> 22259.9 | C65: =B65/B53-1 -> 0.065000742 | E65: =国航自动更新!C185 -> 13251.6 | F65: =E65/E53-1 -> 0.046729858 | H65: =国航自动更新!D185 -> 8105.5 | I65: =H65/H53-1 -> 0.092473785 | K65: =国航自动更新!E185 -> 902.8 | L65: =K65/K53-1 -> 0.098430466 | N65: =国航自动更新!F185 -> 18700.6 | O65: =N65/N53-1 -> 0.082931349 | Q65: =国航自动更新!G185 -> 11410.8 | R65: =Q65/Q53-1 -> 0.064311231 | T65: =国航自动更新!H185 -> 6545.3 | U65: =T65/T53-1 -> 0.11152057 | W65: =国航自动更新!I185 -> 744.5 | X65: =W65/W53-1 -> 0.13042818 | Z65: =国航自动更新!J185 -> 9385.3 | AA65: =Z65/Z53-1 -> 0.07029388 | AC65: =国航自动更新!K185 -> 7551.4 | AD65: =AC65/AC53-1 -> 0.054871064 | AF65: =国航自动更新!L185 -> 1357.7 | AG65: =AF65/AF53-1 -> 0.15020332 | AI65: =国航自动更新!M185 -> 476.1 | AJ65: =AI65/AI53-1 -> 0.10746685 | AL65: =国航自动更新!N185 -> 84 | AM65: =AL65-AL53 -> 1.4 | AO65: =国航自动更新!O185 -> 86.1 | AP65: =AO65-AO53 -> 1.4 | AR65: =国航自动更新!P185 -> 80.8 | AS65: =AR65-AR53 -> 1.4 | AU65: =国航自动更新!Q185 -> 82.5 | AV65: =AU65-AU53 -> 2.4 | AX65: =国航自动更新!R185 -> 673 | AY65: =AX65/AX53-1 -> 0.029051988
A66: 43555 | B66: =国航自动更新!B186 -> 23695.1 | C66: =B66/B54-1 -> 0.043317644 | E66: =国航自动更新!C186 -> 13717.7 | F66: =E66/E54-1 -> 0.010162227 | H66: =国航自动更新!D186 -> 9069 | I66: =H66/H54-1 -> 0.085042234 | K66: =国航自动更新!E186 -> 908.4 | L66: =K66/K54-1 -> 0.17455392 | N66: =国航自动更新!F186 -> 19117.4 | O66: =N66/N54-1 -> 0.029311366 | Q66: =国航自动更新!G186 -> 11237.8 | R66: =Q66/Q54-1 -> -0.013085327 | T66: =国航自动更新!H186 -> 7140.2 | U66: =T66/T54-1 -> 0.085714286 | W66: =国航自动更新!I186 -> 739.4 | X66: =W66/W54-1 -> 0.2125287 | Z66: =国航自动更新!J186 -> 9478.5 | AA66: =Z66/Z54-1 -> 0.012790101 | AC66: =国航自动更新!K186 -> 7534 | AD66: =AC66/AC54-1 -> -0.019380703 | AF66: =国航自动更新!L186 -> 1475.3 | AG66: =AF66/AF54-1 -> 0.14081349 | AI66: =国航自动更新!M186 -> 469.2 | AJ66: =AI66/AI54-1 -> 0.22602561 | AL66: =国航自动更新!N186 -> 80.7 | AM66: =AL66-AL54 -> -1.1 | AO66: =国航自动更新!O186 -> 81.9 | AP66: =AO66-AO54 -> -2 | AR66: =国航自动更新!P186 -> 78.7 | AS66: =AR66-AR54 -> 0 | AU66: =国航自动更新!Q186 -> 81.4 | AV66: =AU66-AU54 -> 2.6 | AX66: =国航自动更新!R186 -> 676 | AY66: =AX66/AX54-1 -> 0.025796662
A67: 43585 | B67: =国航自动更新!B187 -> 23743.8 | C67: =B67/B55-1 -> 0.052021072 | E67: =国航自动更新!C187 -> 13280.5 | F67: =E67/E55-1 -> 0.011716578 | H67: =国航自动更新!D187 -> 9489.4 | I67: =H67/H55-1 -> 0.096406701 | K67: =国航自动更新!E187 -> 973.9 | L67: =K67/K55-1 -> 0.23575688 | N67: =国航自动更新!F187 -> 19224.8 | O67: =N67/N55-1 -> 0.045178267 | Q67: =国航自动更新!G187 -> 10961.3 | R67: =Q67/Q55-1 -> 0.0020110976 | T67: =国航自动更新!H187 -> 7473 | U67: =T67/T55-1 -> 0.098130841 | W67: =国航自动更新!I187 -> 790.5 | X67: =W67/W55-1 -> 0.21746496 | Z67: =国航自动更新!J187 -> 9350.1 | AA67: =Z67/Z55-1 -> 0.020864723 | AC67: =国航自动更新!K187 -> 7371.7 | AD67: =AC67/AC55-1 -> -0.010496785 | AF67: =国航自动更新!L187 -> 1477 | AG67: =AF67/AF55-1 -> 0.14496124 | AI67: =国航自动更新!M187 -> 501.4 | AJ67: =AI67/AI55-1 -> 0.19608779 | AL67: =国航自动更新!N187 -> 81 | AM67: =AL67-AL55 -> -0.5 | AO67: =国航自动更新!O187 -> 82.5 | AP67: =AO67-AO55 -> -0.8 | AR67: =国航自动更新!P187 -> 78.8 | AS67: =AR67-AR55 -> 0.2 | AU67: =国航自动更新!Q187 -> 81.2 | AV67: =AU67-AU55 -> -1.2 | AX67: =国航自动更新!R187 -> 672 | AY67: =AX67/AX55-1 -> 0.021276596
A68: 43616 | B68: =国航自动更新!B188 -> 24215.9 | C68: =B68/B56-1 -> 0.05520502 | E68: =国航自动更新!C188 -> 13723.8 | F68: =E68/E56-1 -> 0.022569276 | H68: =国航自动更新!D188 -> 9506.4 | I68: =H68/H56-1 -> 0.090946648 | K68: =国航自动更新!E188 -> 985.6 | L68: =K68/K56-1 -> 0.21036473 | N68: =国航自动更新!F188 -> 19399.9 | O68: =N68/N56-1 -> 0.083484594 | Q68: =国航自动更新!G188 -> 11179.4 | R68: =Q68/Q56-1 -> 0.043779469 | T68: =国航自动更新!H188 -> 7440.2 | U68: =T68/T56-1 -> 0.13639418 | W68: =国航自动更新!I188 -> 780.4 | X68: =W68/W56-1 -> 0.20543713 | Z68: =国航自动更新!J188 -> 9494.3 | AA68: =Z68/Z56-1 -> 0.066655432 | AC68: =国航自动更新!K188 -> 7572.6 | AD68: =AC68/AC56-1 -> 0.042411728 | AF68: =国航自动更新!L188 -> 1426.5 | AG68: =AF68/AF56-1 -> 0.16145579 | AI68: =国航自动更新!M188 -> 495.2 | AJ68: =AI68/AI56-1 -> 0.2128337 | AL68: =国航自动更新!N188 -> 80.1 | AM68: =AL68-AL56 -> 2.1 | AO68: =国航自动更新!O188 -> 81.5 | AP68: =AO68-AO56 -> 1.7 | AR68: =国航自动更新!P188 -> 78.3 | AS68: =AR68-AR56 -> 3.2 | AU68: =国航自动更新!Q188 -> 79.2 | AV68: =AU68-AU56 -> -0.3 | AX68: =国航自动更新!R188 -> 675 | AY68: =AX68/AX56-1 -> 0.02118003
A69: 43646 | B69: =国航自动更新!B189 -> 23449.5 | C69: =B69/B57-1 -> 0.041959192 | E69: =国航自动更新!C189 -> 13206.1 | F69: =E69/E57-1 -> 0.011512125 | H69: =国航自动更新!D189 -> 9284.6 | I69: =H69/H57-1 -> 0.074718431 | K69: =国航自动更新!E189 -> 958.8 | L69: =K69/K57-1 -> 0.18311945 | N69: =国航自动更新!F189 -> 18889.5 | O69: =N69/N57-1 -> 0.047647307 | Q69: =国航自动更新!G189 -> 10842.5 | R69: =Q69/Q57-1 -> 0.012806621 | T69: =国航自动更新!H189 -> 7287.1 | U69: =T69/T57-1 -> 0.091618605 | W69: =国航自动更新!I189 -> 759.9 | X69: =W69/W57-1 -> 0.16997691 | Z69: =国航自动更新!J189 -> 9192.4 | AA69: =Z69/Z57-1 -> 0.02719857 | AC69: =国航自动更新!K189 -> 7320.4 | AD69: =AC69/AC57-1 -> 0.0065034167 | AF69: =国航自动更新!L189 -> 1383 | AG69: =AF69/AF57-1 -> 0.094925184 | AI69: =国航自动更新!M189 -> 489 | AJ69: =AI69/AI57-1 -> 0.18459302 | AL69: =国航自动更新!N189 -> 80.6 | AM69: =AL69-AL57 -> 0.5 | AO69: =国航自动更新!O189 -> 82.1 | AP69: =AO69-AO57 -> 0.1 | AR69: =国航自动更新!P189 -> 78.5 | AS69: =AR69-AR57 -> 1.2 | AU69: =国航自动更新!Q189 -> 79.3 | AV69: =AU69-AU57 -> -0.9 | AX69: =国航自动更新!R189 -> 676 | AY69: =AX69/AX57-1 -> 0.021148036
A70: 43677 | B70: =国航自动更新!B190 -> 25165.9 | C70: =B70/B58-1 -> 0.056250184 | E70: =国航自动更新!C190 -> 14569.8 | F70: =E70/E58-1 -> 0.074389794 | H70: =国航自动更新!D190 -> 9603.7 | I70: =H70/H58-1 -> 0.020562794 | K70: =国航自动更新!E190 -> 992.5 | L70: =K70/K58-1 -> 0.16149795 | N70: =国航自动更新!F190 -> 20418.4 | O70: =N70/N58-1 -> 0.06412341 | Q70: =国航自动更新!G190 -> 12103.7 | R70: =Q70/Q58-1 -> 0.080697149 | T70: =国航自动更新!H190 -> 7520.8 | U70: =T70/T58-1 -> 0.032367879 | W70: =国航自动更新!I190 -> 793.8 | X70: =W70/W58-1 -> 0.12900014 | Z70: =国航自动更新!J190 -> 10051.2 | AA70: =Z70/Z58-1 -> 0.069344852 | AC70: =国航自动更新!K190 -> 8092.4 | AD70: =AC70/AC58-1 -> 0.06814852 | AF70: =国航自动更新!L190 -> 1440.7 | AG70: =AF70/AF58-1 -> 0.052758495 | AI70: =国航自动更新!M190 -> 518.1 | AJ70: =AI70/AI58-1 -> 0.13943259 | AL70: =国航自动更新!N190 -> 81.1 | AM70: =AL70-AL58 -> 0.6 | AO70: =国航自动更新!O190 -> 83.1 | AP70: =AO70-AO58 -> 0.5 | AR70: =国航自动更新!P190 -> 78.3 | AS70: =AR70-AR58 -> 0.9 | AU70: =国航自动更新!Q190 -> 80 | AV70: =AU70-AU58 -> -2.3 | AX70: =国航自动更新!R190 -> 679 | AY70: =AX70/AX58-1 -> 0.02413273
A71: 43708 | B71: =国航自动更新!B191 -> 25175.8 | C71: =B71/B59-1 -> 0.05571304 | E71: =国航自动更新!C191 -> 14668.4 | F71: =E71/E59-1 -> 0.073192859 | H71: =国航自动更新!D191 -> 9580.1 | I71: =H71/H59-1 -> 0.028647203 | K71: =国航自动更新!E191 -> 927.3 | L71: =K71/K59-1 -> 0.070908881 | N71: =国航自动更新!F191 -> 21296.8 | O71: =N71/N59-1 -> 0.062009744 | Q71: =国航自动更新!G191 -> 12635.7 | R71: =Q71/Q59-1 -> 0.070568001 | T71: =国航自动更新!H191 -> 7944.4 | U71: =T71/T59-1 -> 0.059267457 | W71: =国航自动更新!I191 -> 716.7 | X71: =W71/W59-1 -> -0.045291062 | Z71: =国航自动更新!J191 -> 10480 | AA71: =Z71/Z59-1 -> 0.059035146 | AC71: =国航自动更新!K191 -> 8473.8 | AD71: =AC71/AC59-1 -> 0.060497597 | AF71: =国航自动更新!L191 -> 1530.4 | AG71: =AF71/AF59-1 -> 0.074341874 | AI71: =国航自动更新!M191 -> 475.7 | AJ71: =AI71/AI59-1 -> -0.010813059 | AL71: =国航自动更新!N191 -> 84.6 | AM71: =AL71-AL59 -> 0.5 | AO71: =国航自动更新!O191 -> 86.1 | AP71: =AO71-AO59 -> -0.3 | AR71: =国航自动更新!P191 -> 82.9 | AS71: =AR71-AR59 -> 2.4 | AU71: =国航自动更新!Q191 -> 77.3 | AV71: =AU71-AU59 -> -9.4 | AX71: =国航自动更新!R191 -> 678 | AY71: =AX71/AX59-1 -> 0.01497006
...

Sheet 南方航空
A1: 指标名称 | B1: 可用座公里（百万） | C1: 同比上年 | D1: 同比19 | E1: 可用座公里:国内 | F1: 同比上年 | G1: 同比19 | H1: 可用座公里:国际 | I1: 同比上年 | J1: 同比19 | K1: 可用座公里:地区 | L1: 同比上年 | M1: 同比19 | N1: 收入客公里（百万） | O1: 同比上年 | P1: 同比19 | Q1: 收入客公里:国内 | R1: 同比上年 | S1: 同比19 | T1: 收入客公里:国际 | U1: 同比上年 | V1: 同比19 | W1: 收入客公里:地区 | X1: 同比上年 | Y1: 同比19 | Z1: 客运量（千人次） | AA1: 同比上年 | AB1: 同比19 | AC1: 客运量:国内 | AD1: 同比上年 | AE1: 同比19 | AF1: 客运量:国际 | AG1: 同比上年 | AH1: 同比19 | AI1: 客运量:地区 | AJ1: 同比上年 | AK1: 同比19 | AL1: 客座率 | AM1: 同比上年 | AN1: 同比19 | AO1: 客座率:国内 | AP1: 同比上年 | AQ1: 同比19 | AR1: 客座率:国际 | AS1: 同比上年 | AT1: 同比19 | AU1: 客座率:地区 | AV1: 同比上年 | AW1: 同比19 | AX1: 运营飞机数 | AY1: 同比上年 | AZ1: 同比19
A2: 频率 | B2: 月 | E2: 月 | H2: 月 | K2: 月 | N2: 月 | Q2: 月 | T2: 月 | W2: 月 | Z2: 月 | AC2: 月 | AF2: 月 | AI2: 月 | AL2: 月 | AO2: 月 | AR2: 月 | AU2: 月
B3: ASK | E3: Domestic | H3: International | K3: Regional | N3: RPK | Q3: Domestic | T3: International | W3: Regional | Z3: Pax volume | AC3: Domestic | AF3: International | AI3: Regional | AL3: PLF | AO3: Domestic | AR3: International | AU3: Regional
A4: 41670 | B4: =南航自动更新!B154 -> 17392.78 | E4: =南航自动更新!C154 -> 13175.67 | H4: =南航自动更新!D154 -> 3861.34 | K4: =南航自动更新!E154 -> 355.78 | N4: =南航自动更新!F154 -> 13703.67 | Q4: =南航自动更新!G154 -> 10456.44 | T4: =南航自动更新!H154 -> 3004.42 | W4: =南航自动更新!I154 -> 242.81 | Z4: =南航自动更新!J154 -> 8064.37 | AC4: =南航自动更新!K154 -> 7136.69 | AF4: =南航自动更新!L154 -> 737.53 | AI4: =南航自动更新!M154 -> 190.15 | AL4: =南航自动更新!N154 -> 78.8 | AO4: =南航自动更新!O154 -> 79.4 | AR4: =南航自动更新!P154 -> 77.8 | AU4: =南航自动更新!Q154 -> 68.2 | AX4: =南航自动更新!R154 -> 0
A5: 41698 | B5: =南航自动更新!B155 -> 16291.4 | E5: =南航自动更新!C155 -> 12453.16 | H5: =南航自动更新!D155 -> 3508.26 | K5: =南航自动更新!E155 -> 329.98 | N5: =南航自动更新!F155 -> 13622.57 | Q5: =南航自动更新!G155 -> 10632.03 | T5: =南航自动更新!H155 -> 2742.79 | W5: =南航自动更新!I155 -> 247.74 | Z5: =南航自动更新!J155 -> 8119.94 | AC5: =南航自动更新!K155 -> 7214.23 | AF5: =南航自动更新!L155 -> 713.21 | AI5: =南航自动更新!M155 -> 192.5 | AL5: =南航自动更新!N155 -> 83.62 | AO5: =南航自动更新!O155 -> 85.38 | AR5: =南航自动更新!P155 -> 78.18 | AU5: =南航自动更新!Q155 -> 75.08 | AX5: =南航自动更新!R155 -> 0
A6: 41729 | B6: =南航自动更新!B156 -> 16516.43 | E6: =南航自动更新!C156 -> 12656.77 | H6: =南航自动更新!D156 -> 3525.76 | K6: =南航自动更新!E156 -> 333.9 | N6: =南航自动更新!F156 -> 12878.98 | Q6: =南航自动更新!G156 -> 9980.46 | T6: =南航自动更新!H156 -> 2652.18 | W6: =南航自动更新!I156 -> 246.34 | Z6: =南航自动更新!J156 -> 7776.95 | AC6: =南航自动更新!K156 -> 6907.97 | AF6: =南航自动更新!L156 -> 684.26 | AI6: =南航自动更新!M156 -> 184.72 | AL6: =南航自动更新!N156 -> 77.98 | AO6: =南航自动更新!O156 -> 78.85 | AR6: =南航自动更新!P156 -> 75.22 | AU6: =南航自动更新!Q156 -> 73.78 | AX6: =南航自动更新!R156 -> 0
A7: 41759 | B7: =南航自动更新!B157 -> 16111.46 | E7: =南航自动更新!C157 -> 12335.24 | H7: =南航自动更新!D157 -> 3403.01 | K7: =南航自动更新!E157 -> 373.22 | N7: =南航自动更新!F157 -> 12807.55 | Q7: =南航自动更新!G157 -> 9851.16 | T7: =南航自动更新!H157 -> 2674.7 | W7: =南航自动更新!I157 -> 281.69 | Z7: =南航自动更新!J157 -> 7915.46 | AC7: =南航自动更新!K157 -> 7001.39 | AF7: =南航自动更新!L157 -> 702.68 | AI7: =南航自动更新!M157 -> 211.39 | AL7: =南航自动更新!N157 -> 79.49 | AO7: =南航自动更新!O157 -> 79.86 | AR7: =南航自动更新!P157 -> 78.6 | AU7: =南航自动更新!Q157 -> 75.48 | AX7: =南航自动更新!R157 -> 0
A8: 41790 | B8: =南航自动更新!B158 -> 16257.53 | E8: =南航自动更新!C158 -> 12497.14 | H8: =南航自动更新!D158 -> 3376.85 | K8: =南航自动更新!E158 -> 383.54 | N8: =南航自动更新!F158 -> 12608.99 | Q8: =南航自动更新!G158 -> 9801.15 | T8: =南航自动更新!H158 -> 2532.93 | W8: =南航自动更新!I158 -> 274.91 | Z8: =南航自动更新!J158 -> 7863.87 | AC8: =南航自动更新!K158 -> 7010.85 | AF8: =南航自动更新!L158 -> 651.44 | AI8: =南航自动更新!M158 -> 201.58 | AL8: =南航自动更新!N158 -> 77.56 | AO8: =南航自动更新!O158 -> 78.43 | AR8: =南航自动更新!P158 -> 75.01 | AU8: =南航自动更新!Q158 -> 71.68 | AX8: =南航自动更新!R158 -> 0
A9: 41820 | B9: =南航自动更新!B159 -> 15814.08 | E9: =南航自动更新!C159 -> 12239.75 | H9: =南航自动更新!D159 -> 3215.94 | K9: =南航自动更新!E159 -> 358.4 | N9: =南航自动更新!F159 -> 12317.56 | Q9: =南航自动更新!G159 -> 9581.59 | T9: =南航自动更新!H159 -> 2473.34 | W9: =南航自动更新!I159 -> 262.63 | Z9: =南航自动更新!J159 -> 7644.58 | AC9: =南航自动更新!K159 -> 6837.11 | AF9: =南航自动更新!L159 -> 616.52 | AI9: =南航自动更新!M159 -> 190.95 | AL9: =南航自动更新!N159 -> 77.9 | AO9: =南航自动更新!O159 -> 78.3 | AR9: =南航自动更新!P159 -> 76.9 | AU9: =南航自动更新!Q159 -> 73.3 | AX9: =南航自动更新!R159 -> 0
A10: 41851 | B10: =南航自动更新!B160 -> 19019.31 | E10: =南航自动更新!C160 -> 14849.91 | H10: =南航自动更新!D160 -> 3781.86 | K10: =南航自动更新!E160 -> 387.54 | N10: =南航自动更新!F160 -> 15256.42 | Q10: =南航自动更新!G160 -> 11889.79 | T10: =南航自动更新!H160 -> 3078.03 | W10: =南航自动更新!I160 -> 288.6 | Z10: =南航自动更新!J160 -> 9458.5 | AC10: =南航自动更新!K160 -> 8427.69 | AF10: =南航自动更新!L160 -> 816.56 | AI10: =南航自动更新!M160 -> 214.25 | AL10: =南航自动更新!N160 -> 80.22 | AO10: =南航自动更新!O160 -> 80.07 | AR10: =南航自动更新!P160 -> 81.39 | AU10: =南航自动更新!Q160 -> 74.47 | AX10: =南航自动更新!R160 -> 0
